Workbook

Sheet 使用說明
A1: 台灣勞基法暨勞健保薪資計算系統（115年／2026年版）
A3: 製表基準 | B3: 適用期間：115年1月1日起（最低工資 29,500 元）。製表日：2026/06/11。所有費率與分級表均依勞動部、勞保局、健保署最新公告建置，來源詳「法規注意事項」與各級距表表頭。
A5: 工作表結構 | B5: 各欄位「手動填寫／自動計算」之逐欄對照與填寫時機，請見「欄位填寫指南」工作表。
A6: 1. 法規注意事項 | B6: 勞基法、勞保、就保、職保、健保、勞退、補充保費等計薪相關法規重點、法源依據與官方來源連結。
A7: 2. 參數設定 | B7: 全系統唯一的費率／負擔比例／基準日來源。每年僅需更新此表與四張級距表，全簿公式自動連動。
A8: 3. 勞保／職保／健保／勞退級距表 | B8: 115年官方分級表（含公告文號），供員工清單自動帶出投保級距。
A9: 4. 員工清單 | B9: 員工基本資料主檔：月薪資總額由「薪資結構」帶入、眷屬數由「眷屬名冊」自動統計；自動算年資、特休與四種投保級距。
A10: 5. 薪資總表 | B10: 每月薪資計算總表：填入加班時數、獎金、請假時數等變動項，自動計算應發、代扣、實發與雇主負擔、公司總成本。
A11: 6. 薪資條 | B11: 選擇員工編號即自動帶出該員當月明細，可直接列印或另存 PDF 通知員工。
A12: 7. 結構／稅務／彙總 | B12: 眷屬名冊（一對多，健保/報稅雙旗標）、薪資結構（工資項目＋最低工資檢核）、所得稅扣繳對照、獎金扣繳試算、部門成本彙總。
A13: 每月操作步驟
A14: 步驟 1 | B14: 確認「參數設定」之計算基準日與「薪資總表」B1 發薪年月。
A15: 步驟 2 | B15: 在「員工清單」維護異動（新進、離職、調薪、眷屬異動、自提率）。藍字欄位為輸入，其餘自動計算。
A16: 步驟 3 | B16: 在「薪資總表」填入當月變動：加班時數、獎金、累計獎金、請假時數、代扣所得稅、其他加扣項。
A17: 步驟 4 | B17: 核對合計列與勞保局／健保署繳款單（計費四捨五入或有 ±1 元差異，以繳款單為準）。
A18: 步驟 5 | B18: 至「薪資條」逐一選擇員工編號 → 檔案 → 列印 → 另存為 PDF，寄送員工（勞基法第23條要求提供工資各項目計算方式明細）。
A19: 步驟 6 | B19: 工資清冊（本檔）依勞基法第23條至少保存 5 年。
A21: 顏色圖例
A22: 藍色字 | B22: 人工輸入欄位（基本資料、時數、金額）。
A23: 黑色字 | B23: 公式自動計算，請勿覆寫。
A24: 綠色字 | B24: 跨工作表連結帶入之資料。
A25: 黃色底 | B25: 須依公司實際情況確認之假設（如職保行業別費率、公司名稱、基準日）。
A26: 標題底色 | B26: 橘色標題欄＝人事手動填寫；深藍標題欄＝公式自動計算（逐欄說明見「欄位填寫指南」）。
A27: 年度維護排程 | B27: 每年 11–12 月勞動部／健保署公告次年度級距與費率後：(1) 更新「參數設定」基本工資與費率；(2) 重貼四張級距表；(3) 確認特休、請假規則是否修法。勞保費率依勞保條例每兩年調升 0.5%，下次調升預定 116 年 1 月（屆時含就保合計 13%）。
A28: 批次寄送薪資條 | B28: Microsoft 365 環境可用 Power Automate：以 Excel Online (Business) 連接器逐列讀取「薪資總表」，套版產生 PDF 後由 Outlook 寄送各員工；或以 Word 合併列印連結本檔。
A29: 免責聲明 | B29: 本工具僅供計薪輔助試算。實際保費以勞保局、健保署計費通知為準；職災費率以勞保局核定之行業別費率為準；所得稅扣繳請依當年度財政部「薪資所得扣繳稅額表」辦理。

Sheet 欄位填寫指南
A1: 欄位填寫指南 — 手動填寫 vs 自動計算
A2: 人事只需維護「橘色標題」欄位；「深藍標題」欄位由公式自動計算，請勿改動。儲存格內藍字＝輸入值、黑字＝公式。
A4: 橘色標題＝人事手動填寫 | C4: 深藍標題＝公式自動計算（請勿改動）
A6: 一、員工清單（主檔）— 新進、異動時維護
A7: 欄位 | B7: 欄位名稱 | C7: 性質 | D7: 填寫時機與說明
A8: A | B8: 員工編號 | C8: 手動 | D8: 新進建檔時填寫，請勿重複（建議 E001、E002…）；全簿各表皆以此欄串接。
A9: B | B9: 姓名 | C9: 手動 | D9: 新進建檔時填寫。
A10: C | B10: 部門 | C10: 手動 | D10: 新進建檔；組織異動時更新（「部門成本彙總」依此欄分類）。
A11: D | B11: 職稱 | C11: 手動 | D11: 新進建檔；升遷異動時更新。
A12: E | B12: 到職日 | C12: 手動 | D12: 新進建檔（日期格式，如 2026/3/1）；年資、特休皆由此起算。
A13: F | B13: 年資(月) | C13: 自動 | D13: 依到職日與「參數設定」基準日（C20）以 DATEDIF 計算。
A14: G | B14: 年資 | C14: 自動 | D14: 由 F 欄換算為「○年○月」顯示。
A15: H | B15: 本年特休(日) | C15: 自動 | D15: 依年資查「參數設定」特休對照表（勞基法第38條）。
A16: I | B16: 月薪資總額 | C16: 自動 | D16: 由「薪資結構」表 K 欄（工資項目合計）自動帶入；調薪請至薪資結構修改。
A17: J | B17: 勞保投保薪資 | C17: 自動 | D17: 依 I 欄查勞保級距表（115年上限 45,800）。
A18: K | B18: 職保投保薪資 | C18: 自動 | D18: 依 I 欄查職保級距表（上限 72,800）。
... A30: W | B30: 免稅額申報表收件日 | C30: 手動 | D30: 收到「員工薪資所得受領人免稅額申報表」之日期；到職時及每年1月收件，員工異動後10日內更新。
A32: 二、眷屬名冊 — 眷屬異動隨時維護（每名眷屬一列）
A33: 欄位 | B33: 欄位名稱 | C33: 性質 | D33: 填寫時機與說明
A34: A | B34: 員工編號 | C34: 手動 | D34: 下拉選擇所屬員工；一名員工可登錄多列眷屬（一對多），順序不拘。
A35: B | B35: 員工姓名 | C35: 自動 | D35: 依員編帶出；顯示「⚠查無此員編」（整列紅底）表示員編打錯或該員工已離職清空。
A36: C | B36: 眷屬姓名 | C36: 手動 | D36: 新增眷屬時填寫。
A37: D | B37: 關係 | C37: 手動 | D37: 下拉：配偶／子女／父母／祖父母／兄弟姊妹／其他。
A38: E | B38: 出生年月日 | C38: 手動 | D38: 免稅額申報表必填項目；健保眷屬投保亦需。
A39: F | B39: 身分證字號 | C39: 手動 | D39: 免稅額申報表必填；屬個人資料，請控管檔案權限，亦可留空另冊保管。
A40: G | B40: 依附健保 | C40: 手動 | D40: 「是」＝該眷屬依附本員工投保健保 → 自動計入員工清單 N 欄（健保自付額，計費上限3口）。
A41: H | B41: 報稅扶養 | C41: 手動 | D41: 「是」＝列入免稅額申報表之配偶或受扶養親屬 → 自動計入員工清單 V 欄（墊高查表起扣點）。
A42: I | B42: 備註 | C42: 手動 | D42: 選填（如：眷屬於配偶單位投保、年滿20歲在學證明等）。
A44: 三、薪資結構 — 核薪、調薪時維護（每員工一列）
A45: 欄位 | B45: 欄位名稱 | C45: 性質 | D45: 填寫時機與說明
A46: C | B46: 本薪 | C46: 手動 | D46: 基本底薪；屬工資、應稅。調薪於此修改，I 欄與投保級距自動連動。
A47: D | B47: 主管加給 | C47: 手動 | D47: 擔任主管職務之經常性加給；屬工資、應稅。
A48: E | B48: 職務加給 | C48: 手動 | D48: 特定職務之經常性加給；屬工資、應稅。
A49: F | B49: 專業/技術加給 | C49: 手動 | D49: 證照、語言、技術等經常性加給；屬工資、應稅。
A50: G | B50: 伙食津貼 | C50: 手動 | D50: 每月 3,000 內免稅（參數設定 C28），仍屬工資、計入投保級距；超過部分應稅。
A51: H | B51: 交通津貼 | C51: 手動 | D51: 固定按月發給者屬工資、應稅；實報實銷之代墊性質勿列此欄（改於總表 K 欄處理）。
A52: I | B52: 全勤獎金 | C52: 手動 | D52: 經常性給與屬工資、應稅；當月不符全勤者於薪資總表 W 欄扣回並備註。
A53: J | B53: 其他固定津貼 | C53: 手動 | D53: 其他按月固定發給之經常性給與（如輪班津貼定額）。
A54: K | B54: 月薪資總額 | C54: 自動 | D54: ＝C～J 合計；即投保級距、加班費、平均工資之計算基礎，回寫員工清單 I 欄。
A55: L | B55: 最低工資檢核 | C55: 自動 | D55: 合計低於最低工資（參數設定 C4，115年 29,500）顯示 ⚠ 並整列紅底（勞基法§21、最低工資法）。
...

Sheet 法規注意事項
A1: 計薪相關法規重點與來源（115年／2026年版）
A2: 類別 | B2: 項目 | C2: 重點說明 | D2: 法源依據 | E2: 官方來源／連結
A3: 工資 | B3: 工資定義 | C3: 因工作獲得之報酬，含薪金、獎金、津貼及其他任何名義之「經常性給與」。職務加給、全勤獎金、固定伙食津貼等均屬工資，為加班費與投保級距之計算基礎；年終、三節等恩惠性給與不計。 | D3: 勞動基準法第2條第3款 | E3: https://law.moj.gov.tw/LawClass/LawAll.aspx?pcode=N0030001
A4: 工資 | B4: 最低工資 | C4: 115年1月1日起每月最低工資 29,500 元、每小時 196 元（連續第10年調漲，調幅3.18%）。約定工資低於最低工資者，以最低工資為準。 | D4: 最低工資法第5條；勞動部114.9.26審議決議 | E4: https://www.mol.gov.tw/1607/28162/28166/28180/28182/28188/29025/post
A5: 工資 | B5: 工資給付與薪資明細 | C5: 工資應全額直接、按期（至少每月二次或約定每月一次）給付；雇主應提供工資各項目計算方式明細（薪資條）；工資清冊應保存5年。 | D5: 勞動基準法第22、23條 | E5: https://law.moj.gov.tw/LawClass/LawAll.aspx?pcode=N0030001
A6: 工時 | B6: 正常工時 | C6: 每日不得超過8小時、每週不得超過40小時。 | D6: 勞動基準法第30條 | E6: https://law.moj.gov.tw/LawClass/LawAll.aspx?pcode=N0030001
A7: 工時 | B7: 平日延長工時加給 | C7: 前2小時：平日每小時工資×1又1/3；再延長2小時：×1又2/3。時薪基準＝月薪÷30÷8（本表以÷240計）。 | D7: 勞動基準法第24條第1項 | E7: https://law.moj.gov.tw/LawClass/LawAll.aspx?pcode=N0030001
A8: 工時 | B8: 休息日出勤加給 | C8: 前2小時×1又1/3，第3小時起×1又2/3，按實際出勤時數計算。 | D8: 勞動基準法第24條第2、3項 | E8: https://law.moj.gov.tw/LawClass/LawAll.aspx?pcode=N0030001
A9: 工時 | B9: 加班上限 | C9: 延長工時連同正常工時每日不得超過12小時；每月加班上限46小時（經工會或勞資會議同意得至54小時，每3個月不得超過138小時）。 | D9: 勞動基準法第32條 | E9: https://law.moj.gov.tw/LawClass/LawAll.aspx?pcode=N0030001
A10: 休假 | B10: 例假與休息日 | C10: 每7日應有2日休息，1日為例假、1日為休息日（七休一）。例假僅天災、事變或突發事件可使出勤，且工資加倍並補假。 | D10: 勞動基準法第36、40條 | E10: https://law.moj.gov.tw/LawClass/LawAll.aspx?pcode=N0030001
A11: 休假 | B11: 國定假日出勤 | C11: 休假日（國定假日）工資照給；經同意出勤者，工資加倍發給（即另加發1日工資；未滿8小時亦同，本表以時數×1倍估算，請依函釋調整）。 | D11: 勞動基準法第37、39條 | E11: https://law.moj.gov.tw/LawClass/LawAll.aspx?pcode=N0030001
A12: 休假 | B12: 特別休假 | C12: 6個月以上未滿1年3日；1年7日；2年10日；3年14日；5年15日；10年以上每年加1日至上限30日。年度終結或離職未休畢日數應折發工資。 | D12: 勞動基準法第38條 | E12: https://law.moj.gov.tw/LawClass/LawAll.aspx?pcode=N0030001
A13: 請假 | B13: 事假／普通傷病假 | C13: 事假每年14日內，期間不給工資（本表以日薪比例扣薪）；普通傷病假未住院每年30日內，工資折半發給。 | D13: 勞工請假規則第4、7條 | E13: https://law.moj.gov.tw/LawClass/LawAll.aspx?pcode=N0030006
... A28: 稅務 | B28: 薪資所得扣繳 | C28: 固定薪資依「薪資所得扣繳稅額表」或一律5%擇一扣繳；非固定獎金單次給付超過當年度起扣標準者扣繳5%。本表「代扣所得稅」為人工輸入欄。 | D28: 各類所得扣繳率標準第2條 | E28: https://www.mof.gov.tw

Sheet 參數設定
A1: 參數設定（全簿公式之唯一來源；藍字＝輸入，黃底＝須依公司確認）
A2: 項目 | B2: 代號 | C2: 數值 | D2: 說明 | E2: 法源／來源 | G2: 特休對照（年資月數下限） | H2: 特休天數
A3: 適用年度 | B3: C3 | C3: 115年（2026年） | D3: 1月1日起生效 | E3: 勞動部公告 | G3: 0 | H3: 0
A4: 最低工資（月） | B4: C4 | C4: 29500 | D4: 投保下限、最低工資檢核 | E4: 最低工資法第5條 | G4: 6 | H4: 3
A5: 最低工資（時） | B5: C5 | C5: 196 | D5: 時薪制人員下限 | E5: 同上 | G5: 12 | H5: 7
A6: 勞保普通事故費率 | B6: C6 | C6: 0.115 | D6: 115年維持11.5% | E6: 勞保條例第13條 | G6: 24 | H6: 10
A7: 就業保險費率 | B7: C7 | C7: 0.01 | D7: 與勞保費合併計收 | E7: 就業保險法第8條 | G7: 36 | H7: 14
A8: 勞保＋就保合計費率 | B8: C8 | C8: =C6+C7 -> 0.125 | D8: 12.5% | E8: — | G8: 60 | H8: 15
A9: 勞就保 勞工負擔比例 | B9: C9 | C9: 0.2 | D9: 雇主70%、政府10% | E9: 勞保條例第15條 | G9: 120 | H9: 16
A10: 勞就保 雇主負擔比例 | B10: C10 | C10: 0.7 | E10: 同上 | G10: 132 | H10: 17
A11: 職保費率（行業別＋上下班） | B11: C11 | C11: 0.0021 | D11: 全產業平均約0.21%，請改為勞保局核定之本公司費率；全額雇主負擔 | E11: 災保法第16、19條 | G11: 144 | H11: 18
A12: 健保費率 | B12: C12 | C12: 0.0517 | D12: 115年維持不變 | E12: 健保法第18條 | G12: 156 | H12: 19
A13: 健保 勞工負擔比例 | B13: C13 | C13: 0.3 | D13: 雇主60%、政府10%（第1類受僱者） | E13: 健保法第27條 | G13: 168 | H13: 20
A14: 健保 雇主負擔比例 | B14: C14 | C14: 0.6 | E14: 同上 | G14: 180 | H14: 21
A15: 健保平均眷口數（雇主） | B15: C15 | C15: 0.56 | D15: 雇主負擔＝投保金額×費率×60%×(1+0.56) | E15: 健保署公告 | G15: 192 | H15: 22
A16: 眷屬計費上限（口） | B16: C16 | C16: 3 | D16: 員工自付眷屬超過3口以3口計 | E16: 健保法第29條 | G16: 204 | H16: 23
A17: 勞退雇主提繳率 | B17: C17 | C17: 0.06 | D17: 不得低於6% | E17: 勞退條例第14條 | G17: 216 | H17: 24
A18: 二代健保補充保費率 | B18: C18 | C18: 0.0211 | D18: 個人與投保單位適用 | E18: 健保法第31、34條 | G18: 228 | H18: 25
A19: 月計薪時數（時薪換算） | B19: C19 | C19: 240 | D19: 時薪＝月薪資總額÷240（=30日×8小時） | E19: 勞基法施行細則 | G19: 240 | H19: 26
A20: 年資／特休 計算基準日 | B20: C20 | C20: 46174 | D20: 通常設為週年制之年度結算日或當月1日 | E20: — | G20: 252 | H20: 27
A21: 薪資扣繳起扣標準（0扶養） | B21: C21 | C21: 90501 | D21: 查表法起扣點；獎金等非每月給付未達此數免扣繳 | E21: 財政部稅務入口網（115年度為90,501元） | G21: 264 | H21: 28
A22: 每名配偶/扶養親屬月提高額 | B22: C22 | C22: 8417 | D22: 查表起扣點(n人)≒90,501＋n×8,417（115年免稅額101,000÷12，估算） | E22: 所得稅法第17條、財政部115年度公告 | G22: 276 | H22: 29
A23: 固定5%扣繳率（月薪5%法／獎金） | B23: C23 | C23: 0.05 | D23: 居住者按月擇用5%法、及非每月給付（年終/三節）均適用 | E23: 各類所得扣繳率標準第2條 | G23: 288 | H23: 30
A24: 每月應扣繳稅額免扣上限 | B24: C24 | C24: 2000 | D24: 固定5%法：ROUND(月薪×5%)≤2,000免予扣繳 | E24: 各類所得扣繳率標準第13條 | G24: 依勞基法第38條；以 DATEDIF 月數查表（週年制）
A25: 非居住者全月薪資門檻 | B25: C25 | C25: =ROUND(C4*1.5,0) -> 44250 | D25: 基本工資×1.5（115年＝44,250） | E25: 各類所得扣繳率標準第2條
A26: 非居住者扣繳率（≤門檻） | B26: C26 | C26: 0.06 | D26: 在台未滿183天者 | E26: 同上
A27: 非居住者扣繳率（>門檻） | B27: C27 | C27: 0.18 | E27: 同上
A28: 伙食費免稅額（月） | B28: C28 | C28: 3000 | D28: 免稅額內不計應稅所得，仍屬工資、計入投保級距 | E28: 財政部公告（114年1月起由2,400調為3,000）

Sheet 勞保級距表
A1: 115年 勞工保險投保薪資分級表（全時受僱勞工，共11級）
A2: 資料來源：勞動部114.11.21勞動保2字第1140091863號令修正發布，自115.1.1施行。下載：https://www.bli.gov.tw/0005475.html
A3: 投保等級 | B3: 月薪資總額下限 | C3: 月薪資總額上限 | D3: 月投保金額（級距）
A4: 1 | B4: 0 | C4: 29500 | D4: 29500
A5: 2 | B5: 29501 | C5: 30300 | D5: 30300
A6: 3 | B6: 30301 | C6: 31800 | D6: 31800
A7: 4 | B7: 31801 | C7: 33300 | D7: 33300
A8: 5 | B8: 33301 | C8: 34800 | D8: 34800
A9: 6 | B9: 34801 | C9: 36300 | D9: 36300
A10: 7 | B10: 36301 | C10: 38200 | D10: 38200
A11: 8 | B11: 38201 | C11: 40100 | D11: 40100
A12: 9 | B12: 40101 | C12: 42000 | D12: 42000
A13: 10 | B13: 42001 | C13: 43900 | D13: 43900
A14: 11 | B14: 43901 | C14: 43,901以上 | D14: 45800
A15: 註：月薪資總額介於兩級距間者，以較高等級之投保金額申報；下限欄為本表 VLOOKUP 查表用輔助值。

Sheet 職保級距表
A1: 115年 勞工職業災害保險投保薪資分級表（共21級，上限72,800）
A2: 資料來源：勞動部公告，自115.1.1施行（下限＝最低工資29,500）。下載：https://www.bli.gov.tw/0103450.html
A3: 投保等級 | B3: 月薪資總額下限 | C3: 月薪資總額上限 | D3: 月投保金額（級距）
A4: 1 | B4: 0 | C4: 29500 | D4: 29500
A5: 2 | B5: 29501 | C5: 30300 | D5: 30300
A6: 3 | B6: 30301 | C6: 31800 | D6: 31800
A7: 4 | B7: 31801 | C7: 33300 | D7: 33300
A8: 5 | B8: 33301 | C8: 34800 | D8: 34800
A9: 6 | B9: 34801 | C9: 36300 | D9: 36300
A10: 7 | B10: 36301 | C10: 38200 | D10: 38200
A11: 8 | B11: 38201 | C11: 40100 | D11: 40100
A12: 9 | B12: 40101 | C12: 42000 | D12: 42000
A13: 10 | B13: 42001 | C13: 43900 | D13: 43900
A14: 11 | B14: 43901 | C14: 45800 | D14: 45800
A15: 12 | B15: 45801 | C15: 48200 | D15: 48200
... A23: 20 | B23: 66801 | C23: 69800 | D23: 69800
A24: 21 | B24: 69801 | C24: 69,801以上 | D24: 72800
A25: 註：月薪資總額介於兩級距間者，以較高等級之投保金額申報；下限欄為本表 VLOOKUP 查表用輔助值。

Sheet 健保級距表
A1: 115年 全民健康保險投保金額分級表（共58級，上限313,000）
A2: 資料來源：衛福部114.12.12衛部保字第1140153424號令發布，自115.1.1施行。https://www.nhi.gov.tw/ch/cp-19421-f9533-2569-1.html
A3: 投保等級 | B3: 月薪資總額下限 | C3: 月薪資總額上限 | D3: 月投保金額（級距）
A4: 1 | B4: 0 | C4: 29500 | D4: 29500
A5: 2 | B5: 29501 | C5: 30300 | D5: 30300
A6: 3 | B6: 30301 | C6: 31800 | D6: 31800
A7: 4 | B7: 31801 | C7: 33300 | D7: 33300
A8: 5 | B8: 33301 | C8: 34800 | D8: 34800
A9: 6 | B9: 34801 | C9: 36300 | D9: 36300
A10: 7 | B10: 36301 | C10: 38200 | D10: 38200
A11: 8 | B11: 38201 | C11: 40100 | D11: 40100
A12: 9 | B12: 40101 | C12: 42000 | D12: 42000
A13: 10 | B13: 42001 | C13: 43900 | D13: 43900
A14: 11 | B14: 43901 | C14: 45800 | D14: 45800
A15: 12 | B15: 45801 | C15: 48200 | D15: 48200
... A60: 57 | B60: 293001 | C60: 303000 | D60: 303000
A61: 58 | B61: 303001 | C61: 303,001以上 | D61: 313000
A62: 註：月薪資總額介於兩級距間者，以較高等級之投保金額申報；下限欄為本表 VLOOKUP 查表用輔助值。

Sheet 勞退級距表
A1: 115年 勞工退休金月提繳分級表（共62級，上限150,000）
A2: 資料來源：勞動部114.11.24勞動福3字第1140153598號令修正發布，自115.1.1施行。下載：https://www.bli.gov.tw/0012959.html
A3: 投保等級 | B3: 月薪資總額下限 | C3: 月薪資總額上限 | D3: 月投保金額（級距）
A4: 1 | B4: 0 | C4: 1500 | D4: 1500
A5: 2 | B5: 1501 | C5: 3000 | D5: 3000
A6: 3 | B6: 3001 | C6: 4500 | D6: 4500
A7: 4 | B7: 4501 | C7: 6000 | D7: 6000
A8: 5 | B8: 6001 | C8: 7500 | D8: 7500
A9: 6 | B9: 7501 | C9: 8700 | D9: 8700
A10: 7 | B10: 8701 | C10: 9900 | D10: 9900
A11: 8 | B11: 9901 | C11: 11100 | D11: 11100
A12: 9 | B12: 11101 | C12: 12540 | D12: 12540
A13: 10 | B13: 12541 | C13: 13500 | D13: 13500
A14: 11 | B14: 13501 | C14: 15840 | D14: 15840
A15: 12 | B15: 15841 | C15: 16500 | D15: 16500
... A64: 61 | B64: 142501 | C64: 147900 | D64: 147900
A65: 62 | B65: 147901 | C65: 147,901以上 | D65: 150000
A66: 註：月薪資總額介於兩級距間者，以較高等級之投保金額申報；下限欄為本表 VLOOKUP 查表用輔助值。

Sheet 員工清單
A1: 員工清單（主檔）—藍字輸入；月薪資總額由「薪資結構」帶入，年資、特休、投保級距自動計算
A2: 【橘色標題欄＝人事填寫；深藍標題欄＝自動計算，勿改】月薪資總額由「薪資結構」帶入；健保眷屬數與扶養親屬數由「眷屬名冊」自動統計。新進／離職請於勞保局、健保署當日完成加退保。
A3: 員工編號 | B3: 姓名 | C3: 部門 | D3: 職稱 | E3: 到職日 | F3: 年資(月) | G3: 年資 | H3: 本年特休(日) | I3: 月薪資總額 | J3: 勞保投保薪資 | K3: 職保投保薪資 | L3: 健保投保金額 | M3: 勞退月提繳工資 | N3: 健保眷屬數 （名冊統計） | O3: 計費眷口數 | P3: 勞退自提率 | Q3: 備註 | R3: 成本中心 | S3: 專案別 | T3: 稅務身分 | U3: 扣繳方式 | V3: 配偶+扶養親屬數 （名冊統計） | W3: 免稅額申報表收件日
A4: E001 | B4: 王小明 | C4: 資訊部 | D4: 工程師 | E4: 43525 | F4: =IF(OR($A4="",$E4=""),"",DATEDIF($E4,參數設定!$C$20,"M")) -> 87 | G4: =IF($F4="","",INT($F4/12)&"年"&MOD($F4,12)&"月") -> 7年3月 | H4: =IF($F4="","",VLOOKUP($F4,參數設定!$G$3:$H$23,2,TRUE())) -> 15 | I4: =IF($A4="","",薪資結構!K4) -> 65000 | J4: =IF(OR($A4="",$I4=""),"",VLOOKUP($I4,勞保級距表!$B$4:$D$14,3,TRUE())) -> 45800 | K4: =IF(OR($A4="",$I4=""),"",VLOOKUP($I4,職保級距表!$B$4:$D$24,3,TRUE())) -> 66800 | L4: =IF(OR($A4="",$I4=""),"",VLOOKUP($I4,健保級距表!$B$4:$D$61,3,TRUE())) -> 66800 | M4: =IF(OR($A4="",$I4=""),"",VLOOKUP($I4,勞退級距表!$B$4:$D$65,3,TRUE())) -> 66800 | N4: =IF($A4="","",COUNTIFS(眷屬名冊!$A$4:$A$203,$A4,眷屬名冊!$G$4:$G$203,"是")) -> 1 | O4: =IF($A4="","",MIN(N(N4),參數設定!$C$16)) -> 1 | P4: 0.06 | R4: CC-300 研發 | S4: PJ-2026A | T4: 居住者 | U4: 固定5% | V4: =IF($A4="","",COUNTIFS(眷屬名冊!$A$4:$A$203,$A4,眷屬名冊!$H$4:$H$203,"是")) -> 1 | W4: 46032
A5: E002 | B5: 李美華 | C5: 行政部 | D5: 行政專員 | E5: 45122 | F5: =IF(OR($A5="",$E5=""),"",DATEDIF($E5,參數設定!$C$20,"M")) -> 34 | G5: =IF($F5="","",INT($F5/12)&"年"&MOD($F5,12)&"月") -> 2年10月 | H5: =IF($F5="","",VLOOKUP($F5,參數設定!$G$3:$H$23,2,TRUE())) -> 10 | I5: =IF($A5="","",薪資結構!K5) -> 36000 | J5: =IF(OR($A5="",$I5=""),"",VLOOKUP($I5,勞保級距表!$B$4:$D$14,3,TRUE())) -> 36300 | K5: =IF(OR($A5="",$I5=""),"",VLOOKUP($I5,職保級距表!$B$4:$D$24,3,TRUE())) -> 36300 | L5: =IF(OR($A5="",$I5=""),"",VLOOKUP($I5,健保級距表!$B$4:$D$61,3,TRUE())) -> 36300 | M5: =IF(OR($A5="",$I5=""),"",VLOOKUP($I5,勞退級距表!$B$4:$D$65,3,TRUE())) -> 36300 | N5: =IF($A5="","",COUNTIFS(眷屬名冊!$A$4:$A$203,$A5,眷屬名冊!$G$4:$G$203,"是")) -> 0 | O5: =IF($A5="","",MIN(N(N5),參數設定!$C$16)) -> 0 | P5: 0 | R5: CC-100 管理 | T5: 居住者 | U5: 依扣繳稅額表 | V5: =IF($A5="","",COUNTIFS(眷屬名冊!$A$4:$A$203,$A5,眷屬名冊!$H$4:$H$203,"是")) -> 0 | W5: 46032
A6: E003 | B6: 張志豪 | C6: 業務部 | D6: 業務經理 | E6: 42499 | F6: =IF(OR($A6="",$E6=""),"",DATEDIF($E6,參數設定!$C$20,"M")) -> 120 | G6: =IF($F6="","",INT($F6/12)&"年"&MOD($F6,12)&"月") -> 10年0月 | H6: =IF($F6="","",VLOOKUP($F6,參數設定!$G$3:$H$23,2,TRUE())) -> 16 | I6: =IF($A6="","",薪資結構!K6) -> 85000 | J6: =IF(OR($A6="",$I6=""),"",VLOOKUP($I6,勞保級距表!$B$4:$D$14,3,TRUE())) -> 45800 | K6: =IF(OR($A6="",$I6=""),"",VLOOKUP($I6,職保級距表!$B$4:$D$24,3,TRUE())) -> 72800 | L6: =IF(OR($A6="",$I6=""),"",VLOOKUP($I6,健保級距表!$B$4:$D$61,3,TRUE())) -> 87600 | M6: =IF(OR($A6="",$I6=""),"",VLOOKUP($I6,勞退級距表!$B$4:$D$65,3,TRUE())) -> 87600 | N6: =IF($A6="","",COUNTIFS(眷屬名冊!$A$4:$A$203,$A6,眷屬名冊!$G$4:$G$203,"是")) -> 2 | O6: =IF($A6="","",MIN(N(N6),參數設定!$C$16)) -> 2 | P6: 0.03 | R6: CC-200 營運 | S6: PJ-2026B | T6: 居住者 | U6: 依扣繳稅額表 | V6: =IF($A6="","",COUNTIFS(眷屬名冊!$A$4:$A$203,$A6,眷屬名冊!$H$4:$H$203,"是")) -> 3 | W6: 46034
A7: E004 | B7: 陳雅婷 | C7: 財務部 | D7: 會計 | E7: 44501 | F7: =IF(OR($A7="",$E7=""),"",DATEDIF($E7,參數設定!$C$20,"M")) -> 55 | G7: =IF($F7="","",INT($F7/12)&"年"&MOD($F7,12)&"月") -> 4年7月 | H7: =IF($F7="","",VLOOKUP($F7,參數設定!$G$3:$H$23,2,TRUE())) -> 14 | I7: =IF($A7="","",薪資結構!K7) -> 42000 | J7: =IF(OR($A7="",$I7=""),"",VLOOKUP($I7,勞保級距表!$B$4:$D$14,3,TRUE())) -> 42000 | K7: =IF(OR($A7="",$I7=""),"",VLOOKUP($I7,職保級距表!$B$4:$D$24,3,TRUE())) -> 42000 | L7: =IF(OR($A7="",$I7=""),"",VLOOKUP($I7,健保級距表!$B$4:$D$61,3,TRUE())) -> 42000 | M7: =IF(OR($A7="",$I7=""),"",VLOOKUP($I7,勞退級距表!$B$4:$D$65,3,TRUE())) -> 42000 | N7: =IF($A7="","",COUNTIFS(眷屬名冊!$A$4:$A$203,$A7,眷屬名冊!$G$4:$G$203,"是")) -> 0 | O7: =IF($A7="","",MIN(N(N7),參數設定!$C$16)) -> 0 | P7: 0 | R7: CC-100 管理 | T7: 居住者 | U7: 固定5% | V7: =IF($A7="","",COUNTIFS(眷屬名冊!$A$4:$A$203,$A7,眷屬名冊!$H$4:$H$203,"是")) -> 0 | W7: 46032
A8: E005 | B8: 林承翰 | C8: 資訊部 | D8: 資深工程師 | E8: 43878 | F8: =IF(OR($A8="",$E8=""),"",DATEDIF($E8,參數設定!$C$20,"M")) -> 75 | G8: =IF($F8="","",INT($F8/12)&"年"&MOD($F8,12)&"月") -> 6年3月 | H8: =IF($F8="","",VLOOKUP($F8,參數設定!$G$3:$H$23,2,TRUE())) -> 15 | I8: =IF($A8="","",薪資結構!K8) -> 78000 | J8: =IF(OR($A8="",$I8=""),"",VLOOKUP($I8,勞保級距表!$B$4:$D$14,3,TRUE())) -> 45800 | K8: =IF(OR($A8="",$I8=""),"",VLOOKUP($I8,職保級距表!$B$4:$D$24,3,TRUE())) -> 72800 | L8: =IF(OR($A8="",$I8=""),"",VLOOKUP($I8,健保級距表!$B$4:$D$61,3,TRUE())) -> 80200 | M8: =IF(OR($A8="",$I8=""),"",VLOOKUP($I8,勞退級距表!$B$4:$D$65,3,TRUE())) -> 80200 | N8: =IF($A8="","",COUNTIFS(眷屬名冊!$A$4:$A$203,$A8,眷屬名冊!$G$4:$G$203,"是")) -> 3 | O8: =IF($A8="","",MIN(N(N8),參數設定!$C$16)) -> 3 | P8: 0.06 | R8: CC-300 研發 | S8: PJ-2026A | T8: 居住者 | U8: 依扣繳稅額表 | V8: =IF($A8="","",COUNTIFS(眷屬名冊!$A$4:$A$203,$A8,眷屬名冊!$H$4:$H$203,"是")) -> 3
A9: E006 | B9: 黃詩涵 | C9: 人資部 | D9: 人資專員 | E9: 45537 | F9: =IF(OR($A9="",$E9=""),"",DATEDIF($E9,參數設定!$C$20,"M")) -> 20 | G9: =IF($F9="","",INT($F9/12)&"年"&MOD($F9,12)&"月") -> 1年8月 | H9: =IF($F9="","",VLOOKUP($F9,參數設定!$G$3:$H$23,2,TRUE())) -> 7 | I9: =IF($A9="","",薪資結構!K9) -> 33000 | J9: =IF(OR($A9="",$I9=""),"",VLOOKUP($I9,勞保級距表!$B$4:$D$14,3,TRUE())) -> 33300 | K9: =IF(OR($A9="",$I9=""),"",VLOOKUP($I9,職保級距表!$B$4:$D$24,3,TRUE())) -> 33300 | L9: =IF(OR($A9="",$I9=""),"",VLOOKUP($I9,健保級距表!$B$4:$D$61,3,TRUE())) -> 33300 | M9: =IF(OR($A9="",$I9=""),"",VLOOKUP($I9,勞退級距表!$B$4:$D$65,3,TRUE())) -> 33300 | N9: =IF($A9="","",COUNTIFS(眷屬名冊!$A$4:$A$203,$A9,眷屬名冊!$G$4:$G$203,"是")) -> 0 | O9: =IF($A9="","",MIN(N(N9),參數設定!$C$16)) -> 0 | P9: 0 | R9: CC-100 管理 | T9: 非居住者 | V9: =IF($A9="","",COUNTIFS(眷屬名冊!$A$4:$A$203,$A9,眷屬名冊!$H$4:$H$203,"是")) -> 0 | W9: 46037
A10: E007 | B10: 吳建宏 | C10: 製造部 | D10: 作業員 | E10: 45992 | F10: =IF(OR($A10="",$E10=""),"",DATEDIF($E10,參數設定!$C$20,"M")) -> 6 | G10: =IF($F10="","",INT($F10/12)&"年"&MOD($F10,12)&"月") -> 0年6月 | H10: =IF($F10="","",VLOOKUP($F10,參數設定!$G$3:$H$23,2,TRUE())) -> 3 | I10: =IF($A10="","",薪資結構!K10) -> 29500 | J10: =IF(OR($A10="",$I10=""),"",VLOOKUP($I10,勞保級距表!$B$4:$D$14,3,TRUE())) -> 29500 | K10: =IF(OR($A10="",$I10=""),"",VLOOKUP($I10,職保級距表!$B$4:$D$24,3,TRUE())) -> 29500 | L10: =IF(OR($A10="",$I10=""),"",VLOOKUP($I10,健保級距表!$B$4:$D$61,3,TRUE())) -> 29500 | M10: =IF(OR($A10="",$I10=""),"",VLOOKUP($I10,勞退級距表!$B$4:$D$65,3,TRUE())) -> 29500 | N10: =IF($A10="","",COUNTIFS(眷屬名冊!$A$4:$A$203,$A10,眷屬名冊!$G$4:$G$203,"是")) -> 4 | O10: =IF($A10="","",MIN(N(N10),參數設定!$C$16)) -> 3 | P10: 0 | Q10: 眷屬4口，自付以3口計 | R10: CC-200 營運 | S10: PJ-2026B | T10: 居住者 | U10: 固定5% | V10: =IF($A10="","",COUNTIFS(眷屬名冊!$A$4:$A$203,$A10,眷屬名冊!$H$4:$H$203,"是")) -> 2 | W10: 46032
A11: E008 | B11: 蔡佩珊 | C11: 總經理室 | D11: 特助 | E11: 41487 | F11: =IF(OR($A11="",$E11=""),"",DATEDIF($E11,參數設定!$C$20,"M")) -> 154 | G11: =IF($F11="","",INT($F11/12)&"年"&MOD($F11,12)&"月") -> 12年10月 | H11: =IF($F11="","",VLOOKUP($F11,參數設定!$G$3:$H$23,2,TRUE())) -> 18 | I11: =IF($A11="","",薪資結構!K11) -> 160000 | J11: =IF(OR($A11="",$I11=""),"",VLOOKUP($I11,勞保級距表!$B$4:$D$14,3,TRUE())) -> 45800 | K11: =IF(OR($A11="",$I11=""),"",VLOOKUP($I11,職保級距表!$B$4:$D$24,3,TRUE())) -> 72800 | L11: =IF(OR($A11="",$I11=""),"",VLOOKUP($I11,健保級距表!$B$4:$D$61,3,TRUE())) -> 162800 | M11: =IF(OR($A11="",$I11=""),"",VLOOKUP($I11,勞退級距表!$B$4:$D$65,3,TRUE())) -> 150000 | N11: =IF($A11="","",COUNTIFS(眷屬名冊!$A$4:$A$203,$A11,眷屬名冊!$G$4:$G$203,"是")) -> 1 | O11: =IF($A11="","",MIN(N(N11),參數設定!$C$16)) -> 1 | P11: 0.06 | Q11: 勞/職/退級距均達上限測試 | R11: CC-100 管理 | S11: PJ-2026A | T11: 居住者 | U11: 依扣繳稅額表 | V11: =IF($A11="","",COUNTIFS(眷屬名冊!$A$4:$A$203,$A11,眷屬名冊!$H$4:$H$203,"是")) -> 1 | W11: 46032
F12: =IF(OR($A12="",$E12=""),"",DATEDIF($E12,參數設定!$C$20,"M")) | G12: =IF($F12="","",INT($F12/12)&"年"&MOD($F12,12)&"月") | H12: =IF($F12="","",VLOOKUP($F12,參數設定!$G$3:$H$23,2,TRUE())) | I12: =IF($A12="","",薪資結構!K12) | J12: =IF(OR($A12="",$I12=""),"",VLOOKUP($I12,勞保級距表!$B$4:$D$14,3,TRUE())) | K12: =IF(OR($A12="",$I12=""),"",VLOOKUP($I12,職保級距表!$B$4:$D$24,3,TRUE())) | L12: =IF(OR($A12="",$I12=""),"",VLOOKUP($I12,健保級距表!$B$4:$D$61,3,TRUE())) | M12: =IF(OR($A12="",$I12=""),"",VLOOKUP($I12,勞退級距表!$B$4:$D$65,3,TRUE())) | N12: =IF($A12="","",COUNTIFS(眷屬名冊!$A$4:$A$203,$A12,眷屬名冊!$G$4:$G$203,"是")) | O12: =IF($A12="","",MIN(N(N12),參數設定!$C$16)) | V12: =IF($A12="","",COUNTIFS(眷屬名冊!$A$4:$A$203,$A12,眷屬名冊!$H$4:$H$203,"是"))
F13: =IF(OR($A13="",$E13=""),"",DATEDIF($E13,參數設定!$C$20,"M")) | G13: =IF($F13="","",INT($F13/12)&"年"&MOD($F13,12)&"月") | H13: =IF($F13="","",VLOOKUP($F13,參數設定!$G$3:$H$23,2,TRUE())) | I13: =IF($A13="","",薪資結構!K13) | J13: =IF(OR($A13="",$I13=""),"",VLOOKUP($I13,勞保級距表!$B$4:$D$14,3,TRUE())) | K13: =IF(OR($A13="",$I13=""),"",VLOOKUP($I13,職保級距表!$B$4:$D$24,3,TRUE())) | L13: =IF(OR($A13="",$I13=""),"",VLOOKUP($I13,健保級距表!$B$4:$D$61,3,TRUE())) | M13: =IF(OR($A13="",$I13=""),"",VLOOKUP($I13,勞退級距表!$B$4:$D$65,3,TRUE())) | N13: =IF($A13="","",COUNTIFS(眷屬名冊!$A$4:$A$203,$A13,眷屬名冊!$G$4:$G$203,"是")) | O13: =IF($A13="","",MIN(N(N13),參數設定!$C$16)) | V13: =IF($A13="","",COUNTIFS(眷屬名冊!$A$4:$A$203,$A13,眷屬名冊!$H$4:$H$203,"是"))
F14: =IF(OR($A14="",$E14=""),"",DATEDIF($E14,參數設定!$C$20,"M")) | G14: =IF($F14="","",INT($F14/12)&"年"&MOD($F14,12)&"月") | H14: =IF($F14="","",VLOOKUP($F14,參數設定!$G$3:$H$23,2,TRUE())) | I14: =IF($A14="","",薪資結構!K14) | J14: =IF(OR($A14="",$I14=""),"",VLOOKUP($I14,勞保級距表!$B$4:$D$14,3,TRUE())) | K14: =IF(OR($A14="",$I14=""),"",VLOOKUP($I14,職保級距表!$B$4:$D$24,3,TRUE())) | L14: =IF(OR($A14="",$I14=""),"",VLOOKUP($I14,健保級距表!$B$4:$D$61,3,TRUE())) | M14: =IF(OR($A14="",$I14=""),"",VLOOKUP($I14,勞退級距表!$B$4:$D$65,3,TRUE())) | N14: =IF($A14="","",COUNTIFS(眷屬名冊!$A$4:$A$203,$A14,眷屬名冊!$G$4:$G$203,"是")) | O14: =IF($A14="","",MIN(N(N14),參數設定!$C$16)) | V14: =IF($A14="","",COUNTIFS(眷屬名冊!$A$4:$A$203,$A14,眷屬名冊!$H$4:$H$203,"是"))
F15: =IF(OR($A15="",$E15=""),"",DATEDIF($E15,參數設定!$C$20,"M")) | G15: =IF($F15="","",INT($F15/12)&"年"&MOD($F15,12)&"月") | H15: =IF($F15="","",VLOOKUP($F15,參數設定!$G$3:$H$23,2,TRUE())) | I15: =IF($A15="","",薪資結構!K15) | J15: =IF(OR($A15="",$I15=""),"",VLOOKUP($I15,勞保級距表!$B$4:$D$14,3,TRUE())) | K15: =IF(OR($A15="",$I15=""),"",VLOOKUP($I15,職保級距表!$B$4:$D$24,3,TRUE())) | L15: =IF(OR($A15="",$I15=""),"",VLOOKUP($I15,健保級距表!$B$4:$D$61,3,TRUE())) | M15: =IF(OR($A15="",$I15=""),"",VLOOKUP($I15,勞退級距表!$B$4:$D$65,3,TRUE())) | N15: =IF($A15="","",COUNTIFS(眷屬名冊!$A$4:$A$203,$A15,眷屬名冊!$G$4:$G$203,"是")) | O15: =IF($A15="","",MIN(N(N15),參數設定!$C$16)) | V15: =IF($A15="","",COUNTIFS(眷屬名冊!$A$4:$A$203,$A15,眷屬名冊!$H$4:$H$203,"是"))
F16: =IF(OR($A16="",$E16=""),"",DATEDIF($E16,參數設定!$C$20,"M")) | G16: =IF($F16="","",INT($F16/12)&"年"&MOD($F16,12)&"月") | H16: =IF($F16="","",VLOOKUP($F16,參數設定!$G$3:$H$23,2,TRUE())) | I16: =IF($A16="","",薪資結構!K16) | J16: =IF(OR($A16="",$I16=""),"",VLOOKUP($I16,勞保級距表!$B$4:$D$14,3,TRUE())) | K16: =IF(OR($A16="",$I16=""),"",VLOOKUP($I16,職保級距表!$B$4:$D$24,3,TRUE())) | L16: =IF(OR($A16="",$I16=""),"",VLOOKUP($I16,健保級距表!$B$4:$D$61,3,TRUE())) | M16: =IF(OR($A16="",$I16=""),"",VLOOKUP($I16,勞退級距表!$B$4:$D$65,3,TRUE())) | N16: =IF($A16="","",COUNTIFS(眷屬名冊!$A$4:$A$203,$A16,眷屬名冊!$G$4:$G$203,"是")) | O16: =IF($A16="","",MIN(N(N16),參數設定!$C$16)) | V16: =IF($A16="","",COUNTIFS(眷屬名冊!$A$4:$A$203,$A16,眷屬名冊!$H$4:$H$203,"是"))
F17: =IF(OR($A17="",$E17=""),"",DATEDIF($E17,參數設定!$C$20,"M")) | G17: =IF($F17="","",INT($F17/12)&"年"&MOD($F17,12)&"月") | H17: =IF($F17="","",VLOOKUP($F17,參數設定!$G$3:$H$23,2,TRUE())) | I17: =IF($A17="","",薪資結構!K17) | J17: =IF(OR($A17="",$I17=""),"",VLOOKUP($I17,勞保級距表!$B$4:$D$14,3,TRUE())) | K17: =IF(OR($A17="",$I17=""),"",VLOOKUP($I17,職保級距表!$B$4:$D$24,3,TRUE())) | L17: =IF(OR($A17="",$I17=""),"",VLOOKUP($I17,健保級距表!$B$4:$D$61,3,TRUE())) | M17: =IF(OR($A17="",$I17=""),"",VLOOKUP($I17,勞退級距表!$B$4:$D$65,3,TRUE())) | N17: =IF($A17="","",COUNTIFS(眷屬名冊!$A$4:$A$203,$A17,眷屬名冊!$G$4:$G$203,"是")) | O17: =IF($A17="","",MIN(N(N17),參數設定!$C$16)) | V17: =IF($A17="","",COUNTIFS(眷屬名冊!$A$4:$A$203,$A17,眷屬名冊!$H$4:$H$203,"是"))
F18: =IF(OR($A18="",$E18=""),"",DATEDIF($E18,參數設定!$C$20,"M")) | G18: =IF($F18="","",INT($F18/12)&"年"&MOD($F18,12)&"月") | H18: =IF($F18="","",VLOOKUP($F18,參數設定!$G$3:$H$23,2,TRUE())) | I18: =IF($A18="","",薪資結構!K18) | J18: =IF(OR($A18="",$I18=""),"",VLOOKUP($I18,勞保級距表!$B$4:$D$14,3,TRUE())) | K18: =IF(OR($A18="",$I18=""),"",VLOOKUP($I18,職保級距表!$B$4:$D$24,3,TRUE())) | L18: =IF(OR($A18="",$I18=""),"",VLOOKUP($I18,健保級距表!$B$4:$D$61,3,TRUE())) | M18: =IF(OR($A18="",$I18=""),"",VLOOKUP($I18,勞退級距表!$B$4:$D$65,3,TRUE())) | N18: =IF($A18="","",COUNTIFS(眷屬名冊!$A$4:$A$203,$A18,眷屬名冊!$G$4:$G$203,"是")) | O18: =IF($A18="","",MIN(N(N18),參數設定!$C$16)) | V18: =IF($A18="","",COUNTIFS(眷屬名冊!$A$4:$A$203,$A18,眷屬名冊!$H$4:$H$203,"是"))
F19: =IF(OR($A19="",$E19=""),"",DATEDIF($E19,參數設定!$C$20,"M")) | G19: =IF($F19="","",INT($F19/12)&"年"&MOD($F19,12)&"月") | H19: =IF($F19="","",VLOOKUP($F19,參數設定!$G$3:$H$23,2,TRUE())) | I19: =IF($A19="","",薪資結構!K19) | J19: =IF(OR($A19="",$I19=""),"",VLOOKUP($I19,勞保級距表!$B$4:$D$14,3,TRUE())) | K19: =IF(OR($A19="",$I19=""),"",VLOOKUP($I19,職保級距表!$B$4:$D$24,3,TRUE())) | L19: =IF(OR($A19="",$I19=""),"",VLOOKUP($I19,健保級距表!$B$4:$D$61,3,TRUE())) | M19: =IF(OR($A19="",$I19=""),"",VLOOKUP($I19,勞退級距表!$B$4:$D$65,3,TRUE())) | N19: =IF($A19="","",COUNTIFS(眷屬名冊!$A$4:$A$203,$A19,眷屬名冊!$G$4:$G$203,"是")) | O19: =IF($A19="","",MIN(N(N19),參數設定!$C$16)) | V19: =IF($A19="","",COUNTIFS(眷屬名冊!$A$4:$A$203,$A19,眷屬名冊!$H$4:$H$203,"是"))
F20: =IF(OR($A20="",$E20=""),"",DATEDIF($E20,參數設定!$C$20,"M")) | G20: =IF($F20="","",INT($F20/12)&"年"&MOD($F20,12)&"月") | H20: =IF($F20="","",VLOOKUP($F20,參數設定!$G$3:$H$23,2,TRUE())) | I20: =IF($A20="","",薪資結構!K20) | J20: =IF(OR($A20="",$I20=""),"",VLOOKUP($I20,勞保級距表!$B$4:$D$14,3,TRUE())) | K20: =IF(OR($A20="",$I20=""),"",VLOOKUP($I20,職保級距表!$B$4:$D$24,3,TRUE())) | L20: =IF(OR($A20="",$I20=""),"",VLOOKUP($I20,健保級距表!$B$4:$D$61,3,TRUE())) | M20: =IF(OR($A20="",$I20=""),"",VLOOKUP($I20,勞退級距表!$B$4:$D$65,3,TRUE())) | N20: =IF($A20="","",COUNTIFS(眷屬名冊!$A$4:$A$203,$A20,眷屬名冊!$G$4:$G$203,"是")) | O20: =IF($A20="","",MIN(N(N20),參數設定!$C$16)) | V20: =IF($A20="","",COUNTIFS(眷屬名冊!$A$4:$A$203,$A20,眷屬名冊!$H$4:$H$203,"是"))
F21: =IF(OR($A21="",$E21=""),"",DATEDIF($E21,參數設定!$C$20,"M")) | G21: =IF($F21="","",INT($F21/12)&"年"&MOD($F21,12)&"月") | H21: =IF($F21="","",VLOOKUP($F21,參數設定!$G$3:$H$23,2,TRUE())) | I21: =IF($A21="","",薪資結構!K21) | J21: =IF(OR($A21="",$I21=""),"",VLOOKUP($I21,勞保級距表!$B$4:$D$14,3,TRUE())) | K21: =IF(OR($A21="",$I21=""),"",VLOOKUP($I21,職保級距表!$B$4:$D$24,3,TRUE())) | L21: =IF(OR($A21="",$I21=""),"",VLOOKUP($I21,健保級距表!$B$4:$D$61,3,TRUE())) | M21: =IF(OR($A21="",$I21=""),"",VLOOKUP($I21,勞退級距表!$B$4:$D$65,3,TRUE())) | N21: =IF($A21="","",COUNTIFS(眷屬名冊!$A$4:$A$203,$A21,眷屬名冊!$G$4:$G$203,"是")) | O21: =IF($A21="","",MIN(N(N21),參數設定!$C$16)) | V21: =IF($A21="","",COUNTIFS(眷屬名冊!$A$4:$A$203,$A21,眷屬名冊!$H$4:$H$203,"是"))
F22: =IF(OR($A22="",$E22=""),"",DATEDIF($E22,參數設定!$C$20,"M")) | G22: =IF($F22="","",INT($F22/12)&"年"&MOD($F22,12)&"月") | H22: =IF($F22="","",VLOOKUP($F22,參數設定!$G$3:$H$23,2,TRUE())) | I22: =IF($A22="","",薪資結構!K22) | J22: =IF(OR($A22="",$I22=""),"",VLOOKUP($I22,勞保級距表!$B$4:$D$14,3,TRUE())) | K22: =IF(OR($A22="",$I22=""),"",VLOOKUP($I22,職保級距表!$B$4:$D$24,3,TRUE())) | L22: =IF(OR($A22="",$I22=""),"",VLOOKUP($I22,健保級距表!$B$4:$D$61,3,TRUE())) | M22: =IF(OR($A22="",$I22=""),"",VLOOKUP($I22,勞退級距表!$B$4:$D$65,3,TRUE())) | N22: =IF($A22="","",COUNTIFS(眷屬名冊!$A$4:$A$203,$A22,眷屬名冊!$G$4:$G$203,"是")) | O22: =IF($A22="","",MIN(N(N22),參數設定!$C$16)) | V22: =IF($A22="","",COUNTIFS(眷屬名冊!$A$4:$A$203,$A22,眷屬名冊!$H$4:$H$203,"是"))
F23: =IF(OR($A23="",$E23=""),"",DATEDIF($E23,參數設定!$C$20,"M")) | G23: =IF($F23="","",INT($F23/12)&"年"&MOD($F23,12)&"月") | H23: =IF($F23="","",VLOOKUP($F23,參數設定!$G$3:$H$23,2,TRUE())) | I23: =IF($A23="","",薪資結構!K23) | J23: =IF(OR($A23="",$I23=""),"",VLOOKUP($I23,勞保級距表!$B$4:$D$14,3,TRUE())) | K23: =IF(OR($A23="",$I23=""),"",VLOOKUP($I23,職保級距表!$B$4:$D$24,3,TRUE())) | L23: =IF(OR($A23="",$I23=""),"",VLOOKUP($I23,健保級距表!$B$4:$D$61,3,TRUE())) | M23: =IF(OR($A23="",$I23=""),"",VLOOKUP($I23,勞退級距表!$B$4:$D$65,3,TRUE())) | N23: =IF($A23="","",COUNTIFS(眷屬名冊!$A$4:$A$203,$A23,眷屬名冊!$G$4:$G$203,"是")) | O23: =IF($A23="","",MIN(N(N23),參數設定!$C$16)) | V23: =IF($A23="","",COUNTIFS(眷屬名冊!$A$4:$A$203,$A23,眷屬名冊!$H$4:$H$203,"是"))
... F53: =IF(OR($A53="",$E53=""),"",DATEDIF($E53,參數設定!$C$20,"M")) | G53: =IF($F53="","",INT($F53/12)&"年"&MOD($F53,12)&"月") | H53: =IF($F53="","",VLOOKUP($F53,參數設定!$G$3:$H$23,2,TRUE())) | I53: =IF($A53="","",薪資結構!K53) | J53: =IF(OR($A53="",$I53=""),"",VLOOKUP($I53,勞保級距表!$B$4:$D$14,3,TRUE())) | K53: =IF(OR($A53="",$I53=""),"",VLOOKUP($I53,職保級距表!$B$4:$D$24,3,TRUE())) | L53: =IF(OR($A53="",$I53=""),"",VLOOKUP($I53,健保級距表!$B$4:$D$61,3,TRUE())) | M53: =IF(OR($A53="",$I53=""),"",VLOOKUP($I53,勞退級距表!$B$4:$D$65,3,TRUE())) | N53: =IF($A53="","",COUNTIFS(眷屬名冊!$A$4:$A$203,$A53,眷屬名冊!$G$4:$G$203,"是")) | O53: =IF($A53="","",MIN(N(N53),參數設定!$C$16)) | V53: =IF($A53="","",COUNTIFS(眷屬名冊!$A$4:$A$203,$A53,眷屬名冊!$H$4:$H$203,"是"))

Sheet 眷屬名冊
A1: 眷屬名冊 — 一名員工可登錄多名眷屬（一對多）
A2: 每名眷屬一列，直接於空白列新增即可（順序不拘）。「依附健保」「報稅扶養」為兩個獨立旗標，員工清單的健保眷屬數（N）與配偶+扶養親屬數（V）將自動統計，無需手動維護。眷屬退保或不再列報扶養，將旗標改「否」或清空整列。身分證字號屬個人資料，請控管檔案存取權限。
A3: 員工編號 | B3: 員工姓名 （自動） | C3: 眷屬姓名 | D3: 關係 | E3: 出生年月日 | F3: 身分證字號 （個資） | G3: 依附健保 →N欄 | H3: 報稅扶養 →V欄 | I3: 備註
A4: E001 | B4: =IF($A4="","",IFERROR(VLOOKUP($A4,員工清單!$A$4:$B$53,2,FALSE()),"⚠查無此員編")) -> 王小明 | C4: 林佳蓉 | D4: 配偶 | E4: 33732 | G4: 是 | H4: 是
A5: E003 | B5: =IF($A5="","",IFERROR(VLOOKUP($A5,員工清單!$A$4:$B$53,2,FALSE()),"⚠查無此員編")) -> 張志豪 | C5: 王淑芬 | D5: 配偶 | E5: 31128 | G5: 是 | H5: 是
A6: E003 | B6: =IF($A6="","",IFERROR(VLOOKUP($A6,員工清單!$A$4:$B$53,2,FALSE()),"⚠查無此員編")) -> 張志豪 | C6: 張小寶 | D6: 子女 | E6: 42248 | G6: 是 | H6: 是
A7: E003 | B7: =IF($A7="","",IFERROR(VLOOKUP($A7,員工清單!$A$4:$B$53,2,FALSE()),"⚠查無此員編")) -> 張志豪 | C7: 張大山 | D7: 父母 | E7: 21200 | G7: 否 | H7: 是
A8: E005 | B8: =IF($A8="","",IFERROR(VLOOKUP($A8,員工清單!$A$4:$B$53,2,FALSE()),"⚠查無此員編")) -> 林承翰 | C8: 陳怡君 | D8: 配偶 | E8: 33179 | G8: 是 | H8: 是
A9: E005 | B9: =IF($A9="","",IFERROR(VLOOKUP($A9,員工清單!$A$4:$B$53,2,FALSE()),"⚠查無此員編")) -> 林承翰 | C9: 林小美 | D9: 子女 | E9: 43208 | G9: 是 | H9: 是
A10: E005 | B10: =IF($A10="","",IFERROR(VLOOKUP($A10,員工清單!$A$4:$B$53,2,FALSE()),"⚠查無此員編")) -> 林承翰 | C10: 林小芳 | D10: 子女 | E10: 44407 | G10: 是 | H10: 是
A11: E007 | B11: =IF($A11="","",IFERROR(VLOOKUP($A11,員工清單!$A$4:$B$53,2,FALSE()),"⚠查無此員編")) -> 吳建宏 | C11: 李秀英 | D11: 配偶 | E11: 32306 | G11: 是 | H11: 是
A12: E007 | B12: =IF($A12="","",IFERROR(VLOOKUP($A12,員工清單!$A$4:$B$53,2,FALSE()),"⚠查無此員編")) -> 吳建宏 | C12: 吳小寶 | D12: 子女 | E12: 42425 | G12: 是 | H12: 是
A13: E007 | B13: =IF($A13="","",IFERROR(VLOOKUP($A13,員工清單!$A$4:$B$53,2,FALSE()),"⚠查無此員編")) -> 吳建宏 | C13: 吳大富 | D13: 父母 | E13: 20304 | G13: 是 | H13: 否
A14: E007 | B14: =IF($A14="","",IFERROR(VLOOKUP($A14,員工清單!$A$4:$B$53,2,FALSE()),"⚠查無此員編")) -> 吳建宏 | C14: 陳金枝 | D14: 父母 | E14: 21163 | G14: 是 | H14: 否
A15: E008 | B15: =IF($A15="","",IFERROR(VLOOKUP($A15,員工清單!$A$4:$B$53,2,FALSE()),"⚠查無此員編")) -> 蔡佩珊 | C15: 蔡小寶 | D15: 子女 | E15: 41917 | G15: 是 | H15: 是
B16: =IF($A16="","",IFERROR(VLOOKUP($A16,員工清單!$A$4:$B$53,2,FALSE()),"⚠查無此員編"))
B17: =IF($A17="","",IFERROR(VLOOKUP($A17,員工清單!$A$4:$B$53,2,FALSE()),"⚠查無此員編"))
B18: =IF($A18="","",IFERROR(VLOOKUP($A18,員工清單!$A$4:$B$53,2,FALSE()),"⚠查無此員編"))
B19: =IF($A19="","",IFERROR(VLOOKUP($A19,員工清單!$A$4:$B$53,2,FALSE()),"⚠查無此員編"))
B20: =IF($A20="","",IFERROR(VLOOKUP($A20,員工清單!$A$4:$B$53,2,FALSE()),"⚠查無此員編"))
B21: =IF($A21="","",IFERROR(VLOOKUP($A21,員工清單!$A$4:$B$53,2,FALSE()),"⚠查無此員編"))
B22: =IF($A22="","",IFERROR(VLOOKUP($A22,員工清單!$A$4:$B$53,2,FALSE()),"⚠查無此員編"))
B23: =IF($A23="","",IFERROR(VLOOKUP($A23,員工清單!$A$4:$B$53,2,FALSE()),"⚠查無此員編"))
B24: =IF($A24="","",IFERROR(VLOOKUP($A24,員工清單!$A$4:$B$53,2,FALSE()),"⚠查無此員編"))
B25: =IF($A25="","",IFERROR(VLOOKUP($A25,員工清單!$A$4:$B$53,2,FALSE()),"⚠查無此員編"))
B26: =IF($A26="","",IFERROR(VLOOKUP($A26,員工清單!$A$4:$B$53,2,FALSE()),"⚠查無此員編"))
B27: =IF($A27="","",IFERROR(VLOOKUP($A27,員工清單!$A$4:$B$53,2,FALSE()),"⚠查無此員編"))
... B203: =IF($A203="","",IFERROR(VLOOKUP($A203,員工清單!$A$4:$B$53,2,FALSE()),"⚠查無此員編"))

Sheet 薪資結構
A1: 薪資結構（月薪制固定工資項目）— 合計即投保級距／加班費／平均工資之計算基礎
A2: 工資認定標準＝「勞務對價＋經常性給與」，與名稱無關（勞基法第2條）。本表各欄均屬工資，合計自動回寫員工清單。年終／三節等非經常性獎金勿列入本表（請用「獎金扣繳試算」與總表L欄）；差旅費等實報實銷代墊款非工資（於總表K欄處理並留憑證）。
A3: 員工編號 | B3: 姓名 | C3: 本薪 工資✓ 應稅✓ | D3: 主管加給 工資✓ 應稅✓ | E3: 職務加給 工資✓ 應稅✓ | F3: 專業/技術加給 工資✓ 應稅✓ | G3: 伙食津貼 工資✓ 3,000內免稅 | H3: 交通津貼 工資✓ 應稅✓ | I3: 全勤獎金 工資✓ 應稅✓ | J3: 其他固定津貼 工資✓ 應稅✓ | K3: 月薪資總額 （投保級距基礎） | L3: 最低工資檢核 （≥參數C4）
A4: =IF(員工清單!A4="","",員工清單!A4) -> E001 | B4: =IF($A4="","",員工清單!B4) -> 王小明 | C4: 54000 | E4: 3000 | F4: 3000 | G4: 3000 | I4: 2000 | K4: =IF($A4="","",SUM(C4:J4)) -> 65000 | L4: =IF($A4="","",IF($K4>=參數設定!$C$4,"✓","⚠ 低於最低工資")) -> ✓
A5: =IF(員工清單!A5="","",員工清單!A5) -> E002 | B5: =IF($A5="","",員工清單!B5) -> 李美華 | C5: 31000 | G5: 3000 | I5: 2000 | K5: =IF($A5="","",SUM(C5:J5)) -> 36000 | L5: =IF($A5="","",IF($K5>=參數設定!$C$4,"✓","⚠ 低於最低工資")) -> ✓
A6: =IF(員工清單!A6="","",員工清單!A6) -> E003 | B6: =IF($A6="","",員工清單!B6) -> 張志豪 | C6: 65000 | D6: 10000 | E6: 5000 | G6: 3000 | H6: 2000 | K6: =IF($A6="","",SUM(C6:J6)) -> 85000 | L6: =IF($A6="","",IF($K6>=參數設定!$C$4,"✓","⚠ 低於最低工資")) -> ✓
A7: =IF(員工清單!A7="","",員工清單!A7) -> E004 | B7: =IF($A7="","",員工清單!B7) -> 陳雅婷 | C7: 34000 | E7: 3000 | G7: 3000 | I7: 2000 | K7: =IF($A7="","",SUM(C7:J7)) -> 42000 | L7: =IF($A7="","",IF($K7>=參數設定!$C$4,"✓","⚠ 低於最低工資")) -> ✓
A8: =IF(員工清單!A8="","",員工清單!A8) -> E005 | B8: =IF($A8="","",員工清單!B8) -> 林承翰 | C8: 64000 | E8: 3000 | F8: 6000 | G8: 3000 | I8: 2000 | K8: =IF($A8="","",SUM(C8:J8)) -> 78000 | L8: =IF($A8="","",IF($K8>=參數設定!$C$4,"✓","⚠ 低於最低工資")) -> ✓
A9: =IF(員工清單!A9="","",員工清單!A9) -> E006 | B9: =IF($A9="","",員工清單!B9) -> 黃詩涵 | C9: 28000 | G9: 3000 | I9: 2000 | K9: =IF($A9="","",SUM(C9:J9)) -> 33000 | L9: =IF($A9="","",IF($K9>=參數設定!$C$4,"✓","⚠ 低於最低工資")) -> ✓
A10: =IF(員工清單!A10="","",員工清單!A10) -> E007 | B10: =IF($A10="","",員工清單!B10) -> 吳建宏 | C10: 24500 | G10: 3000 | I10: 2000 | K10: =IF($A10="","",SUM(C10:J10)) -> 29500 | L10: =IF($A10="","",IF($K10>=參數設定!$C$4,"✓","⚠ 低於最低工資")) -> ✓
A11: =IF(員工清單!A11="","",員工清單!A11) -> E008 | B11: =IF($A11="","",員工清單!B11) -> 蔡佩珊 | C11: 135000 | D11: 15000 | E11: 5000 | G11: 3000 | H11: 2000 | K11: =IF($A11="","",SUM(C11:J11)) -> 160000 | L11: =IF($A11="","",IF($K11>=參數設定!$C$4,"✓","⚠ 低於最低工資")) -> ✓
A12: =IF(員工清單!A12="","",員工清單!A12) | B12: =IF($A12="","",員工清單!B12) | K12: =IF($A12="","",SUM(C12:J12)) | L12: =IF($A12="","",IF($K12>=參數設定!$C$4,"✓","⚠ 低於最低工資"))
A13: =IF(員工清單!A13="","",員工清單!A13) | B13: =IF($A13="","",員工清單!B13) | K13: =IF($A13="","",SUM(C13:J13)) | L13: =IF($A13="","",IF($K13>=參數設定!$C$4,"✓","⚠ 低於最低工資"))
A14: =IF(員工清單!A14="","",員工清單!A14) | B14: =IF($A14="","",員工清單!B14) | K14: =IF($A14="","",SUM(C14:J14)) | L14: =IF($A14="","",IF($K14>=參數設定!$C$4,"✓","⚠ 低於最低工資"))
A15: =IF(員工清單!A15="","",員工清單!A15) | B15: =IF($A15="","",員工清單!B15) | K15: =IF($A15="","",SUM(C15:J15)) | L15: =IF($A15="","",IF($K15>=參數設定!$C$4,"✓","⚠ 低於最低工資"))
A16: =IF(員工清單!A16="","",員工清單!A16) | B16: =IF($A16="","",員工清單!B16) | K16: =IF($A16="","",SUM(C16:J16)) | L16: =IF($A16="","",IF($K16>=參數設定!$C$4,"✓","⚠ 低於最低工資"))
A17: =IF(員工清單!A17="","",員工清單!A17) | B17: =IF($A17="","",員工清單!B17) | K17: =IF($A17="","",SUM(C17:J17)) | L17: =IF($A17="","",IF($K17>=參數設定!$C$4,"✓","⚠ 低於最低工資"))
A18: =IF(員工清單!A18="","",員工清單!A18) | B18: =IF($A18="","",員工清單!B18) | K18: =IF($A18="","",SUM(C18:J18)) | L18: =IF($A18="","",IF($K18>=參數設定!$C$4,"✓","⚠ 低於最低工資"))
A19: =IF(員工清單!A19="","",員工清單!A19) | B19: =IF($A19="","",員工清單!B19) | K19: =IF($A19="","",SUM(C19:J19)) | L19: =IF($A19="","",IF($K19>=參數設定!$C$4,"✓","⚠ 低於最低工資"))
A20: =IF(員工清單!A20="","",員工清單!A20) | B20: =IF($A20="","",員工清單!B20) | K20: =IF($A20="","",SUM(C20:J20)) | L20: =IF($A20="","",IF($K20>=參數設定!$C$4,"✓","⚠ 低於最低工資"))
A21: =IF(員工清單!A21="","",員工清單!A21) | B21: =IF($A21="","",員工清單!B21) | K21: =IF($A21="","",SUM(C21:J21)) | L21: =IF($A21="","",IF($K21>=參數設定!$C$4,"✓","⚠ 低於最低工資"))
A22: =IF(員工清單!A22="","",員工清單!A22) | B22: =IF($A22="","",員工清單!B22) | K22: =IF($A22="","",SUM(C22:J22)) | L22: =IF($A22="","",IF($K22>=參數設定!$C$4,"✓","⚠ 低於最低工資"))
A23: =IF(員工清單!A23="","",員工清單!A23) | B23: =IF($A23="","",員工清單!B23) | K23: =IF($A23="","",SUM(C23:J23)) | L23: =IF($A23="","",IF($K23>=參數設定!$C$4,"✓","⚠ 低於最低工資"))
... A53: =IF(員工清單!A53="","",員工清單!A53) | B53: =IF($A53="","",員工清單!B53) | K53: =IF($A53="","",SUM(C53:J53)) | L53: =IF($A53="","",IF($K53>=參數設定!$C$4,"✓","⚠ 低於最低工資"))
A55: ※ 全勤獎金：當月不符全勤者，請於薪資總表 W 欄（其他扣款）扣回並備註，以保留級距申報之一致性。

Sheet 所得稅扣繳對照
A1: 所得稅扣繳對照表 — 員工免稅額申報資料與每月建議扣繳
A2: 收件依據：「員工薪資所得受領人免稅額申報表」（到職時及每年1月收件、異動後10日內更新）；未填表者依規定按固定5%扣繳。查表起扣點為估算值（90,501＋扶養人數×8,417），薪資接近門檻者請以財政部115年度薪資所得扣繳稅額表為準。
A3: 員工編號 | B3: 姓名 | C3: 稅務身分 | D3: 扣繳方式 | E3: 配偶+扶養人數 | F3: 申報表收件 | G3: 當月應稅薪資(估) | H3: 查表起扣點(估) | I3: 建議代扣稅額 | J3: 提醒
A4: =IF(員工清單!A4="","",員工清單!A4) -> E001 | B4: =IF($A4="","",員工清單!B4) -> 王小明 | C4: =IF($A4="","",IF(員工清單!T4="","居住者",員工清單!T4)) -> 居住者 | D4: =IF($A4="","",IF($C4="非居住者","—(6%/18%)",IF(員工清單!U4="","固定5%(未填表)",員工清單!U4))) -> 固定5% | E4: =IF($A4="","",N(員工清單!V4)) -> 1 | F4: =IF($A4="","",IF(員工清單!W4="","⚠未收件",員工清單!W4)) -> 46032 | G4: =IF($A4="","",薪資總表!M4-薪資總表!J4-薪資總表!L4-薪資總表!S4-MIN(N(薪資結構!G4),參數設定!$C$28)) -> 57992 | H4: =IF($A4="","",IF($C4="非居住者","—",參數設定!$C$21+$E4*參數設定!$C$22)) -> 98918 | I4: =IF($A4="","",IF($C4="非居住者",IF($G4<=參數設定!$C$25,ROUND($G4*參數設定!$C$26,0),ROUND($G4*參數設定!$C$27,0)),IF(LEFT($D4,4)="固定5%",IF(ROUND($G4*參數設定!$C$23,0)<=參數設定!$C$24,0,ROUND($G4*參數設定!$C$23,0)),IF($G4<$H4,0,"查115年扣繳稅額表")))) -> 2900 | J4: =IF($A4="","",TRIM(IF(員工清單!W4="","請補收免稅額申報表。","")&IF(AND($C4<>"非居住者",員工清單!U4="依扣繳稅額表",ISNUMBER($H4),$G4>=$H4)," 達起扣點：請依扶養"&$E4&"人欄查表後填入薪資總表V欄。","")))
A5: =IF(員工清單!A5="","",員工清單!A5) -> E002 | B5: =IF($A5="","",員工清單!B5) -> 李美華 | C5: =IF($A5="","",IF(員工清單!T5="","居住者",員工清單!T5)) -> 居住者 | D5: =IF($A5="","",IF($C5="非居住者","—(6%/18%)",IF(員工清單!U5="","固定5%(未填表)",員工清單!U5))) -> 依扣繳稅額表 | E5: =IF($A5="","",N(員工清單!V5)) -> 0 | F5: =IF($A5="","",IF(員工清單!W5="","⚠未收件",員工清單!W5)) -> 46032 | G5: =IF($A5="","",薪資總表!M5-薪資總表!J5-薪資總表!L5-薪資總表!S5-MIN(N(薪資結構!G5),參數設定!$C$28)) -> 33000 | H5: =IF($A5="","",IF($C5="非居住者","—",參數設定!$C$21+$E5*參數設定!$C$22)) -> 90501 | I5: =IF($A5="","",IF($C5="非居住者",IF($G5<=參數設定!$C$25,ROUND($G5*參數設定!$C$26,0),ROUND($G5*參數設定!$C$27,0)),IF(LEFT($D5,4)="固定5%",IF(ROUND($G5*參數設定!$C$23,0)<=參數設定!$C$24,0,ROUND($G5*參數設定!$C$23,0)),IF($G5<$H5,0,"查115年扣繳稅額表")))) -> 0 | J5: =IF($A5="","",TRIM(IF(員工清單!W5="","請補收免稅額申報表。","")&IF(AND($C5<>"非居住者",員工清單!U5="依扣繳稅額表",ISNUMBER($H5),$G5>=$H5)," 達起扣點：請依扶養"&$E5&"人欄查表後填入薪資總表V欄。","")))
A6: =IF(員工清單!A6="","",員工清單!A6) -> E003 | B6: =IF($A6="","",員工清單!B6) -> 張志豪 | C6: =IF($A6="","",IF(員工清單!T6="","居住者",員工清單!T6)) -> 居住者 | D6: =IF($A6="","",IF($C6="非居住者","—(6%/18%)",IF(員工清單!U6="","固定5%(未填表)",員工清單!U6))) -> 依扣繳稅額表 | E6: =IF($A6="","",N(員工清單!V6)) -> 3 | F6: =IF($A6="","",IF(員工清單!W6="","⚠未收件",員工清單!W6)) -> 46034 | G6: =IF($A6="","",薪資總表!M6-薪資總表!J6-薪資總表!L6-薪資總表!S6-MIN(N(薪資結構!G6),參數設定!$C$28)) -> 79372 | H6: =IF($A6="","",IF($C6="非居住者","—",參數設定!$C$21+$E6*參數設定!$C$22)) -> 115752 | I6: =IF($A6="","",IF($C6="非居住者",IF($G6<=參數設定!$C$25,ROUND($G6*參數設定!$C$26,0),ROUND($G6*參數設定!$C$27,0)),IF(LEFT($D6,4)="固定5%",IF(ROUND($G6*參數設定!$C$23,0)<=參數設定!$C$24,0,ROUND($G6*參數設定!$C$23,0)),IF($G6<$H6,0,"查115年扣繳稅額表")))) -> 0 | J6: =IF($A6="","",TRIM(IF(員工清單!W6="","請補收免稅額申報表。","")&IF(AND($C6<>"非居住者",員工清單!U6="依扣繳稅額表",ISNUMBER($H6),$G6>=$H6)," 達起扣點：請依扶養"&$E6&"人欄查表後填入薪資總表V欄。","")))
A7: =IF(員工清單!A7="","",員工清單!A7) -> E004 | B7: =IF($A7="","",員工清單!B7) -> 陳雅婷 | C7: =IF($A7="","",IF(員工清單!T7="","居住者",員工清單!T7)) -> 居住者 | D7: =IF($A7="","",IF($C7="非居住者","—(6%/18%)",IF(員工清單!U7="","固定5%(未填表)",員工清單!U7))) -> 固定5% | E7: =IF($A7="","",N(員工清單!V7)) -> 0 | F7: =IF($A7="","",IF(員工清單!W7="","⚠未收件",員工清單!W7)) -> 46032 | G7: =IF($A7="","",薪資總表!M7-薪資總表!J7-薪資總表!L7-薪資總表!S7-MIN(N(薪資結構!G7),參數設定!$C$28)) -> 39000 | H7: =IF($A7="","",IF($C7="非居住者","—",參數設定!$C$21+$E7*參數設定!$C$22)) -> 90501 | I7: =IF($A7="","",IF($C7="非居住者",IF($G7<=參數設定!$C$25,ROUND($G7*參數設定!$C$26,0),ROUND($G7*參數設定!$C$27,0)),IF(LEFT($D7,4)="固定5%",IF(ROUND($G7*參數設定!$C$23,0)<=參數設定!$C$24,0,ROUND($G7*參數設定!$C$23,0)),IF($G7<$H7,0,"查115年扣繳稅額表")))) -> 0 | J7: =IF($A7="","",TRIM(IF(員工清單!W7="","請補收免稅額申報表。","")&IF(AND($C7<>"非居住者",員工清單!U7="依扣繳稅額表",ISNUMBER($H7),$G7>=$H7)," 達起扣點：請依扶養"&$E7&"人欄查表後填入薪資總表V欄。","")))
A8: =IF(員工清單!A8="","",員工清單!A8) -> E005 | B8: =IF($A8="","",員工清單!B8) -> 林承翰 | C8: =IF($A8="","",IF(員工清單!T8="","居住者",員工清單!T8)) -> 居住者 | D8: =IF($A8="","",IF($C8="非居住者","—(6%/18%)",IF(員工清單!U8="","固定5%(未填表)",員工清單!U8))) -> 依扣繳稅額表 | E8: =IF($A8="","",N(員工清單!V8)) -> 3 | F8: =IF($A8="","",IF(員工清單!W8="","⚠未收件",員工清單!W8)) -> ⚠未收件 | G8: =IF($A8="","",薪資總表!M8-薪資總表!J8-薪資總表!L8-薪資總表!S8-MIN(N(薪資結構!G8),參數設定!$C$28)) -> 70188 | H8: =IF($A8="","",IF($C8="非居住者","—",參數設定!$C$21+$E8*參數設定!$C$22)) -> 115752 | I8: =IF($A8="","",IF($C8="非居住者",IF($G8<=參數設定!$C$25,ROUND($G8*參數設定!$C$26,0),ROUND($G8*參數設定!$C$27,0)),IF(LEFT($D8,4)="固定5%",IF(ROUND($G8*參數設定!$C$23,0)<=參數設定!$C$24,0,ROUND($G8*參數設定!$C$23,0)),IF($G8<$H8,0,"查115年扣繳稅額表")))) -> 0 | J8: =IF($A8="","",TRIM(IF(員工清單!W8="","請補收免稅額申報表。","")&IF(AND($C8<>"非居住者",員工清單!U8="依扣繳稅額表",ISNUMBER($H8),$G8>=$H8)," 達起扣點：請依扶養"&$E8&"人欄查表後填入薪資總表V欄。",""))) -> 請補收免稅額申報表。
A9: =IF(員工清單!A9="","",員工清單!A9) -> E006 | B9: =IF($A9="","",員工清單!B9) -> 黃詩涵 | C9: =IF($A9="","",IF(員工清單!T9="","居住者",員工清單!T9)) -> 非居住者 | D9: =IF($A9="","",IF($C9="非居住者","—(6%/18%)",IF(員工清單!U9="","固定5%(未填表)",員工清單!U9))) -> —(6%/18%) | E9: =IF($A9="","",N(員工清單!V9)) -> 0 | F9: =IF($A9="","",IF(員工清單!W9="","⚠未收件",員工清單!W9)) -> 46037 | G9: =IF($A9="","",薪資總表!M9-薪資總表!J9-薪資總表!L9-薪資總表!S9-MIN(N(薪資結構!G9),參數設定!$C$28)) -> 30000 | H9: =IF($A9="","",IF($C9="非居住者","—",參數設定!$C$21+$E9*參數設定!$C$22)) -> — | I9: =IF($A9="","",IF($C9="非居住者",IF($G9<=參數設定!$C$25,ROUND($G9*參數設定!$C$26,0),ROUND($G9*參數設定!$C$27,0)),IF(LEFT($D9,4)="固定5%",IF(ROUND($G9*參數設定!$C$23,0)<=參數設定!$C$24,0,ROUND($G9*參數設定!$C$23,0)),IF($G9<$H9,0,"查115年扣繳稅額表")))) -> 1800 | J9: =IF($A9="","",TRIM(IF(員工清單!W9="","請補收免稅額申報表。","")&IF(AND($C9<>"非居住者",員工清單!U9="依扣繳稅額表",ISNUMBER($H9),$G9>=$H9)," 達起扣點：請依扶養"&$E9&"人欄查表後填入薪資總表V欄。","")))
A10: =IF(員工清單!A10="","",員工清單!A10) -> E007 | B10: =IF($A10="","",員工清單!B10) -> 吳建宏 | C10: =IF($A10="","",IF(員工清單!T10="","居住者",員工清單!T10)) -> 居住者 | D10: =IF($A10="","",IF($C10="非居住者","—(6%/18%)",IF(員工清單!U10="","固定5%(未填表)",員工清單!U10))) -> 固定5% | E10: =IF($A10="","",N(員工清單!V10)) -> 2 | F10: =IF($A10="","",IF(員工清單!W10="","⚠未收件",員工清單!W10)) -> 46032 | G10: =IF($A10="","",薪資總表!M10-薪資總表!J10-薪資總表!L10-薪資總表!S10-MIN(N(薪資結構!G10),參數設定!$C$28)) -> 26500 | H10: =IF($A10="","",IF($C10="非居住者","—",參數設定!$C$21+$E10*參數設定!$C$22)) -> 107335 | I10: =IF($A10="","",IF($C10="非居住者",IF($G10<=參數設定!$C$25,ROUND($G10*參數設定!$C$26,0),ROUND($G10*參數設定!$C$27,0)),IF(LEFT($D10,4)="固定5%",IF(ROUND($G10*參數設定!$C$23,0)<=參數設定!$C$24,0,ROUND($G10*參數設定!$C$23,0)),IF($G10<$H10,0,"查115年扣繳稅額表")))) -> 0 | J10: =IF($A10="","",TRIM(IF(員工清單!W10="","請補收免稅額申報表。","")&IF(AND($C10<>"非居住者",員工清單!U10="依扣繳稅額表",ISNUMBER($H10),$G10>=$H10)," 達起扣點：請依扶養"&$E10&"人欄查表後填入薪資總表V欄。","")))
A11: =IF(員工清單!A11="","",員工清單!A11) -> E008 | B11: =IF($A11="","",員工清單!B11) -> 蔡佩珊 | C11: =IF($A11="","",IF(員工清單!T11="","居住者",員工清單!T11)) -> 居住者 | D11: =IF($A11="","",IF($C11="非居住者","—(6%/18%)",IF(員工清單!U11="","固定5%(未填表)",員工清單!U11))) -> 依扣繳稅額表 | E11: =IF($A11="","",N(員工清單!V11)) -> 1 | F11: =IF($A11="","",IF(員工清單!W11="","⚠未收件",員工清單!W11)) -> 46032 | G11: =IF($A11="","",薪資總表!M11-薪資總表!J11-薪資總表!L11-薪資總表!S11-MIN(N(薪資結構!G11),參數設定!$C$28)) -> 148000 | H11: =IF($A11="","",IF($C11="非居住者","—",參數設定!$C$21+$E11*參數設定!$C$22)) -> 98918 | I11: =IF($A11="","",IF($C11="非居住者",IF($G11<=參數設定!$C$25,ROUND($G11*參數設定!$C$26,0),ROUND($G11*參數設定!$C$27,0)),IF(LEFT($D11,4)="固定5%",IF(ROUND($G11*參數設定!$C$23,0)<=參數設定!$C$24,0,ROUND($G11*參數設定!$C$23,0)),IF($G11<$H11,0,"查115年扣繳稅額表")))) -> 查115年扣繳稅額表 | J11: =IF($A11="","",TRIM(IF(員工清單!W11="","請補收免稅額申報表。","")&IF(AND($C11<>"非居住者",員工清單!U11="依扣繳稅額表",ISNUMBER($H11),$G11>=$H11)," 達起扣點：請依扶養"&$E11&"人欄查表後填入薪資總表V欄。",""))) -> 達起扣點：請依扶養1人欄查表後填入薪資總表V欄。
A12: =IF(員工清單!A12="","",員工清單!A12) | B12: =IF($A12="","",員工清單!B12) | C12: =IF($A12="","",IF(員工清單!T12="","居住者",員工清單!T12)) | D12: =IF($A12="","",IF($C12="非居住者","—(6%/18%)",IF(員工清單!U12="","固定5%(未填表)",員工清單!U12))) | E12: =IF($A12="","",N(員工清單!V12)) | F12: =IF($A12="","",IF(員工清單!W12="","⚠未收件",員工清單!W12)) | G12: =IF($A12="","",薪資總表!M12-薪資總表!J12-薪資總表!L12-薪資總表!S12-MIN(N(薪資結構!G12),參數設定!$C$28)) | H12: =IF($A12="","",IF($C12="非居住者","—",參數設定!$C$21+$E12*參數設定!$C$22)) | I12: =IF($A12="","",IF($C12="非居住者",IF($G12<=參數設定!$C$25,ROUND($G12*參數設定!$C$26,0),ROUND($G12*參數設定!$C$27,0)),IF(LEFT($D12,4)="固定5%",IF(ROUND($G12*參數設定!$C$23,0)<=參數設定!$C$24,0,ROUND($G12*參數設定!$C$23,0)),IF($G12<$H12,0,"查115年扣繳稅額表")))) | J12: =IF($A12="","",TRIM(IF(員工清單!W12="","請補收免稅額申報表。","")&IF(AND($C12<>"非居住者",員工清單!U12="依扣繳稅額表",ISNUMBER($H12),$G12>=$H12)," 達起扣點：請依扶養"&$E12&"人欄查表後填入薪資總表V欄。","")))
A13: =IF(員工清單!A13="","",員工清單!A13) | B13: =IF($A13="","",員工清單!B13) | C13: =IF($A13="","",IF(員工清單!T13="","居住者",員工清單!T13)) | D13: =IF($A13="","",IF($C13="非居住者","—(6%/18%)",IF(員工清單!U13="","固定5%(未填表)",員工清單!U13))) | E13: =IF($A13="","",N(員工清單!V13)) | F13: =IF($A13="","",IF(員工清單!W13="","⚠未收件",員工清單!W13)) | G13: =IF($A13="","",薪資總表!M13-薪資總表!J13-薪資總表!L13-薪資總表!S13-MIN(N(薪資結構!G13),參數設定!$C$28)) | H13: =IF($A13="","",IF($C13="非居住者","—",參數設定!$C$21+$E13*參數設定!$C$22)) | I13: =IF($A13="","",IF($C13="非居住者",IF($G13<=參數設定!$C$25,ROUND($G13*參數設定!$C$26,0),ROUND($G13*參數設定!$C$27,0)),IF(LEFT($D13,4)="固定5%",IF(ROUND($G13*參數設定!$C$23,0)<=參數設定!$C$24,0,ROUND($G13*參數設定!$C$23,0)),IF($G13<$H13,0,"查115年扣繳稅額表")))) | J13: =IF($A13="","",TRIM(IF(員工清單!W13="","請補收免稅額申報表。","")&IF(AND($C13<>"非居住者",員工清單!U13="依扣繳稅額表",ISNUMBER($H13),$G13>=$H13)," 達起扣點：請依扶養"&$E13&"人欄查表後填入薪資總表V欄。","")))
A14: =IF(員工清單!A14="","",員工清單!A14) | B14: =IF($A14="","",員工清單!B14) | C14: =IF($A14="","",IF(員工清單!T14="","居住者",員工清單!T14)) | D14: =IF($A14="","",IF($C14="非居住者","—(6%/18%)",IF(員工清單!U14="","固定5%(未填表)",員工清單!U14))) | E14: =IF($A14="","",N(員工清單!V14)) | F14: =IF($A14="","",IF(員工清單!W14="","⚠未收件",員工清單!W14)) | G14: =IF($A14="","",薪資總表!M14-薪資總表!J14-薪資總表!L14-薪資總表!S14-MIN(N(薪資結構!G14),參數設定!$C$28)) | H14: =IF($A14="","",IF($C14="非居住者","—",參數設定!$C$21+$E14*參數設定!$C$22)) | I14: =IF($A14="","",IF($C14="非居住者",IF($G14<=參數設定!$C$25,ROUND($G14*參數設定!$C$26,0),ROUND($G14*參數設定!$C$27,0)),IF(LEFT($D14,4)="固定5%",IF(ROUND($G14*參數設定!$C$23,0)<=參數設定!$C$24,0,ROUND($G14*參數設定!$C$23,0)),IF($G14<$H14,0,"查115年扣繳稅額表")))) | J14: =IF($A14="","",TRIM(IF(員工清單!W14="","請補收免稅額申報表。","")&IF(AND($C14<>"非居住者",員工清單!U14="依扣繳稅額表",ISNUMBER($H14),$G14>=$H14)," 達起扣點：請依扶養"&$E14&"人欄查表後填入薪資總表V欄。","")))
A15: =IF(員工清單!A15="","",員工清單!A15) | B15: =IF($A15="","",員工清單!B15) | C15: =IF($A15="","",IF(員工清單!T15="","居住者",員工清單!T15)) | D15: =IF($A15="","",IF($C15="非居住者","—(6%/18%)",IF(員工清單!U15="","固定5%(未填表)",員工清單!U15))) | E15: =IF($A15="","",N(員工清單!V15)) | F15: =IF($A15="","",IF(員工清單!W15="","⚠未收件",員工清單!W15)) | G15: =IF($A15="","",薪資總表!M15-薪資總表!J15-薪資總表!L15-薪資總表!S15-MIN(N(薪資結構!G15),參數設定!$C$28)) | H15: =IF($A15="","",IF($C15="非居住者","—",參數設定!$C$21+$E15*參數設定!$C$22)) | I15: =IF($A15="","",IF($C15="非居住者",IF($G15<=參數設定!$C$25,ROUND($G15*參數設定!$C$26,0),ROUND($G15*參數設定!$C$27,0)),IF(LEFT($D15,4)="固定5%",IF(ROUND($G15*參數設定!$C$23,0)<=參數設定!$C$24,0,ROUND($G15*參數設定!$C$23,0)),IF($G15<$H15,0,"查115年扣繳稅額表")))) | J15: =IF($A15="","",TRIM(IF(員工清單!W15="","請補收免稅額申報表。","")&IF(AND($C15<>"非居住者",員工清單!U15="依扣繳稅額表",ISNUMBER($H15),$G15>=$H15)," 達起扣點：請依扶養"&$E15&"人欄查表後填入薪資總表V欄。","")))
... A53: =IF(員工清單!A53="","",員工清單!A53) | B53: =IF($A53="","",員工清單!B53) | C53: =IF($A53="","",IF(員工清單!T53="","居住者",員工清單!T53)) | D53: =IF($A53="","",IF($C53="非居住者","—(6%/18%)",IF(員工清單!U53="","固定5%(未填表)",員工清單!U53))) | E53: =IF($A53="","",N(員工清單!V53)) | F53: =IF($A53="","",IF(員工清單!W53="","⚠未收件",員工清單!W53)) | G53: =IF($A53="","",薪資總表!M53-薪資總表!J53-薪資總表!L53-薪資總表!S53-MIN(N(薪資結構!G53),參數設定!$C$28)) | H53: =IF($A53="","",IF($C53="非居住者","—",參數設定!$C$21+$E53*參數設定!$C$22)) | I53: =IF($A53="","",IF($C53="非居住者",IF($G53<=參數設定!$C$25,ROUND($G53*參數設定!$C$26,0),ROUND($G53*參數設定!$C$27,0)),IF(LEFT($D53,4)="固定5%",IF(ROUND($G53*參數設定!$C$23,0)<=參數設定!$C$24,0,ROUND($G53*參數設定!$C$23,0)),IF($G53<$H53,0,"查115年扣繳稅額表")))) | J53: =IF($A53="","",TRIM(IF(員工清單!W53="","請補收免稅額申報表。","")&IF(AND($C53<>"非居住者",員工清單!U53="依扣繳稅額表",ISNUMBER($H53),$G53>=$H53)," 達起扣點：請依扶養"&$E53&"人欄查表後填入薪資總表V欄。","")))
A55: ※ 法源：各類所得扣繳率標準第2、13條 — 居住者可擇「查表」或「固定5%」；每月應扣繳稅額不超過2,000元者免扣；非居住者全月給付≤44,250按6%、超過按18%。
A56: ※ 本表「當月應稅薪資(估)」＝薪資總表應發合計 − 加班費（法定標準內免稅）− 當月獎金（另按5%計）− 勞退自提（免稅）− 伙食津貼免稅額內金額（每月3,000，自「薪資結構」G欄帶入）。
A57: ※ 請將「建議代扣稅額」轉填入薪資總表 V 欄；顯示「查115年扣繳稅額表」者，依財政部公告表按扶養人數欄查得稅額後填入。

Sheet 薪資總表
A1: 發薪年月： | B1: 115年01月 | D1: 每月薪資計算總表｜橘色標題欄＝當月手動填寫（時數、獎金、稅、扣款），深藍標題欄＝自動計算勿改；儲存格藍字＝輸入值、黑字＝公式；金額均四捨五入至元
A2: 員工資料 | E2: 加項（應發） | N2: 減項（代扣） | Z2: 雇主負擔（公司成本）
A3: 員工編號 | B3: 姓名 | C3: 部門 | D3: 月薪資總額 | E3: 平日加班時數(×1.34) | F3: 平日加班時數(×1.67) | G3: 休息日加班(×1.34) | H3: 休息日加班(×1.67) | I3: 假日出勤時數(×1) | J3: 加班費 | K3: 其他加項 | L3: 當月獎金 | M3: 應發合計 | N3: 事假時數 | O3: 病假時數 | P3: 請假扣款 | Q3: 勞保費(自付) | R3: 健保費(自付含眷屬) | S3: 勞退自提 | T3: 年度累計獎金(含本月) | U3: 獎金補充保費 | V3: 代扣所得稅 | W3: 其他扣款 | X3: 扣款合計 | Y3: 實發金額 | Z3: 勞保費(雇主) | AA3: 職保費(雇主) | AB3: 健保費(雇主) | AC3: 勞退提繳(雇主6%) | AD3: 雇主負擔合計 | AE3: 雇主總成本
A4: =IF(員工清單!A4="","",員工清單!A4) -> E001 | B4: =IF($A4="","",員工清單!B4) -> 王小明 | C4: =IF($A4="","",員工清單!C4) -> 資訊部 | D4: =IF($A4="","",員工清單!I4) -> 65000 | E4: 6 | J4: =IF($A4="","",ROUND($D4/參數設定!$C$19*(E4*4/3+F4*5/3+G4*4/3+H4*5/3+I4),0)) -> 2167 | L4: 0 | M4: =IF($A4="","",ROUND(D4+J4+K4+L4,0)) -> 67167 | P4: =IF($A4="","",ROUND($D4/參數設定!$C$19*(N4+O4*0.5),0)) -> 0 | Q4: =IF($A4="","",ROUND(員工清單!J4*參數設定!$C$8*參數設定!$C$9,0)) -> 1145 | R4: =IF($A4="","",ROUND(員工清單!L4*參數設定!$C$12*參數設定!$C$13,0)*(1+員工清單!O4)) -> 2072 | S4: =IF($A4="","",ROUND(員工清單!M4*N(員工清單!P4),0)) -> 4008 | T4: 0 | U4: =IF($A4="","",ROUND(MIN(N(L4),MAX(0,N(T4)-員工清單!L4*4))*參數設定!$C$18,0)) -> 0 | X4: =IF($A4="","",P4+Q4+R4+S4+U4+V4+W4) -> 7225 | Y4: =IF($A4="","",M4-X4) -> 59942 | Z4: =IF($A4="","",ROUND(員工清單!J4*參數設定!$C$8*參數設定!$C$10,0)) -> 4007 | AA4: =IF($A4="","",ROUND(員工清單!K4*參數設定!$C$11,0)) -> 140 | AB4: =IF($A4="","",ROUND(員工清單!L4*參數設定!$C$12*參數設定!$C$14*(1+參數設定!$C$15),0)) -> 3233 | AC4: =IF($A4="","",ROUND(員工清單!M4*參數設定!$C$17,0)) -> 4008 | AD4: =IF($A4="","",Z4+AA4+AB4+AC4) -> 11388 | AE4: =IF($A4="","",M4+AD4) -> 78555
A5: =IF(員工清單!A5="","",員工清單!A5) -> E002 | B5: =IF($A5="","",員工清單!B5) -> 李美華 | C5: =IF($A5="","",員工清單!C5) -> 行政部 | D5: =IF($A5="","",員工清單!I5) -> 36000 | E5: 2 | G5: 4 | J5: =IF($A5="","",ROUND($D5/參數設定!$C$19*(E5*4/3+F5*5/3+G5*4/3+H5*5/3+I5),0)) -> 1200 | M5: =IF($A5="","",ROUND(D5+J5+K5+L5,0)) -> 37200 | P5: =IF($A5="","",ROUND($D5/參數設定!$C$19*(N5+O5*0.5),0)) -> 0 | Q5: =IF($A5="","",ROUND(員工清單!J5*參數設定!$C$8*參數設定!$C$9,0)) -> 908 | R5: =IF($A5="","",ROUND(員工清單!L5*參數設定!$C$12*參數設定!$C$13,0)*(1+員工清單!O5)) -> 563 | S5: =IF($A5="","",ROUND(員工清單!M5*N(員工清單!P5),0)) -> 0 | U5: =IF($A5="","",ROUND(MIN(N(L5),MAX(0,N(T5)-員工清單!L5*4))*參數設定!$C$18,0)) -> 0 | X5: =IF($A5="","",P5+Q5+R5+S5+U5+V5+W5) -> 1471 | Y5: =IF($A5="","",M5-X5) -> 35729 | Z5: =IF($A5="","",ROUND(員工清單!J5*參數設定!$C$8*參數設定!$C$10,0)) -> 3176 | AA5: =IF($A5="","",ROUND(員工清單!K5*參數設定!$C$11,0)) -> 76 | AB5: =IF($A5="","",ROUND(員工清單!L5*參數設定!$C$12*參數設定!$C$14*(1+參數設定!$C$15),0)) -> 1757 | AC5: =IF($A5="","",ROUND(員工清單!M5*參數設定!$C$17,0)) -> 2178 | AD5: =IF($A5="","",Z5+AA5+AB5+AC5) -> 7187 | AE5: =IF($A5="","",M5+AD5) -> 44387
A6: =IF(員工清單!A6="","",員工清單!A6) -> E003 | B6: =IF($A6="","",員工清單!B6) -> 張志豪 | C6: =IF($A6="","",員工清單!C6) -> 業務部 | D6: =IF($A6="","",員工清單!I6) -> 85000 | J6: =IF($A6="","",ROUND($D6/參數設定!$C$19*(E6*4/3+F6*5/3+G6*4/3+H6*5/3+I6),0)) -> 0 | L6: 50000 | M6: =IF($A6="","",ROUND(D6+J6+K6+L6,0)) -> 135000 | P6: =IF($A6="","",ROUND($D6/參數設定!$C$19*(N6+O6*0.5),0)) -> 0 | Q6: =IF($A6="","",ROUND(員工清單!J6*參數設定!$C$8*參數設定!$C$9,0)) -> 1145 | R6: =IF($A6="","",ROUND(員工清單!L6*參數設定!$C$12*參數設定!$C$13,0)*(1+員工清單!O6)) -> 4077 | S6: =IF($A6="","",ROUND(員工清單!M6*N(員工清單!P6),0)) -> 2628 | T6: 50000 | U6: =IF($A6="","",ROUND(MIN(N(L6),MAX(0,N(T6)-員工清單!L6*4))*參數設定!$C$18,0)) -> 0 | X6: =IF($A6="","",P6+Q6+R6+S6+U6+V6+W6) -> 7850 | Y6: =IF($A6="","",M6-X6) -> 127150 | Z6: =IF($A6="","",ROUND(員工清單!J6*參數設定!$C$8*參數設定!$C$10,0)) -> 4007 | AA6: =IF($A6="","",ROUND(員工清單!K6*參數設定!$C$11,0)) -> 153 | AB6: =IF($A6="","",ROUND(員工清單!L6*參數設定!$C$12*參數設定!$C$14*(1+參數設定!$C$15),0)) -> 4239 | AC6: =IF($A6="","",ROUND(員工清單!M6*參數設定!$C$17,0)) -> 5256 | AD6: =IF($A6="","",Z6+AA6+AB6+AC6) -> 13655 | AE6: =IF($A6="","",M6+AD6) -> 148655
A7: =IF(員工清單!A7="","",員工清單!A7) -> E004 | B7: =IF($A7="","",員工清單!B7) -> 陳雅婷 | C7: =IF($A7="","",員工清單!C7) -> 財務部 | D7: =IF($A7="","",員工清單!I7) -> 42000 | J7: =IF($A7="","",ROUND($D7/參數設定!$C$19*(E7*4/3+F7*5/3+G7*4/3+H7*5/3+I7),0)) -> 0 | M7: =IF($A7="","",ROUND(D7+J7+K7+L7,0)) -> 42000 | N7: 4 | P7: =IF($A7="","",ROUND($D7/參數設定!$C$19*(N7+O7*0.5),0)) -> 700 | Q7: =IF($A7="","",ROUND(員工清單!J7*參數設定!$C$8*參數設定!$C$9,0)) -> 1050 | R7: =IF($A7="","",ROUND(員工清單!L7*參數設定!$C$12*參數設定!$C$13,0)*(1+員工清單!O7)) -> 651 | S7: =IF($A7="","",ROUND(員工清單!M7*N(員工清單!P7),0)) -> 0 | U7: =IF($A7="","",ROUND(MIN(N(L7),MAX(0,N(T7)-員工清單!L7*4))*參數設定!$C$18,0)) -> 0 | X7: =IF($A7="","",P7+Q7+R7+S7+U7+V7+W7) -> 2401 | Y7: =IF($A7="","",M7-X7) -> 39599 | Z7: =IF($A7="","",ROUND(員工清單!J7*參數設定!$C$8*參數設定!$C$10,0)) -> 3675 | AA7: =IF($A7="","",ROUND(員工清單!K7*參數設定!$C$11,0)) -> 88 | AB7: =IF($A7="","",ROUND(員工清單!L7*參數設定!$C$12*參數設定!$C$14*(1+參數設定!$C$15),0)) -> 2032 | AC7: =IF($A7="","",ROUND(員工清單!M7*參數設定!$C$17,0)) -> 2520 | AD7: =IF($A7="","",Z7+AA7+AB7+AC7) -> 8315 | AE7: =IF($A7="","",M7+AD7) -> 50315
A8: =IF(員工清單!A8="","",員工清單!A8) -> E005 | B8: =IF($A8="","",員工清單!B8) -> 林承翰 | C8: =IF($A8="","",員工清單!C8) -> 資訊部 | D8: =IF($A8="","",員工清單!I8) -> 78000 | E8: 8 | F8: 2 | J8: =IF($A8="","",ROUND($D8/參數設定!$C$19*(E8*4/3+F8*5/3+G8*4/3+H8*5/3+I8),0)) -> 4550 | M8: =IF($A8="","",ROUND(D8+J8+K8+L8,0)) -> 82550 | P8: =IF($A8="","",ROUND($D8/參數設定!$C$19*(N8+O8*0.5),0)) -> 0 | Q8: =IF($A8="","",ROUND(員工清單!J8*參數設定!$C$8*參數設定!$C$9,0)) -> 1145 | R8: =IF($A8="","",ROUND(員工清單!L8*參數設定!$C$12*參數設定!$C$13,0)*(1+員工清單!O8)) -> 4976 | S8: =IF($A8="","",ROUND(員工清單!M8*N(員工清單!P8),0)) -> 4812 | U8: =IF($A8="","",ROUND(MIN(N(L8),MAX(0,N(T8)-員工清單!L8*4))*參數設定!$C$18,0)) -> 0 | X8: =IF($A8="","",P8+Q8+R8+S8+U8+V8+W8) -> 10933 | Y8: =IF($A8="","",M8-X8) -> 71617 | Z8: =IF($A8="","",ROUND(員工清單!J8*參數設定!$C$8*參數設定!$C$10,0)) -> 4007 | AA8: =IF($A8="","",ROUND(員工清單!K8*參數設定!$C$11,0)) -> 153 | AB8: =IF($A8="","",ROUND(員工清單!L8*參數設定!$C$12*參數設定!$C$14*(1+參數設定!$C$15),0)) -> 3881 | AC8: =IF($A8="","",ROUND(員工清單!M8*參數設定!$C$17,0)) -> 4812 | AD8: =IF($A8="","",Z8+AA8+AB8+AC8) -> 12853 | AE8: =IF($A8="","",M8+AD8) -> 95403
A9: =IF(員工清單!A9="","",員工清單!A9) -> E006 | B9: =IF($A9="","",員工清單!B9) -> 黃詩涵 | C9: =IF($A9="","",員工清單!C9) -> 人資部 | D9: =IF($A9="","",員工清單!I9) -> 33000 | J9: =IF($A9="","",ROUND($D9/參數設定!$C$19*(E9*4/3+F9*5/3+G9*4/3+H9*5/3+I9),0)) -> 0 | M9: =IF($A9="","",ROUND(D9+J9+K9+L9,0)) -> 33000 | P9: =IF($A9="","",ROUND($D9/參數設定!$C$19*(N9+O9*0.5),0)) -> 0 | Q9: =IF($A9="","",ROUND(員工清單!J9*參數設定!$C$8*參數設定!$C$9,0)) -> 833 | R9: =IF($A9="","",ROUND(員工清單!L9*參數設定!$C$12*參數設定!$C$13,0)*(1+員工清單!O9)) -> 516 | S9: =IF($A9="","",ROUND(員工清單!M9*N(員工清單!P9),0)) -> 0 | U9: =IF($A9="","",ROUND(MIN(N(L9),MAX(0,N(T9)-員工清單!L9*4))*參數設定!$C$18,0)) -> 0 | X9: =IF($A9="","",P9+Q9+R9+S9+U9+V9+W9) -> 1349 | Y9: =IF($A9="","",M9-X9) -> 31651 | Z9: =IF($A9="","",ROUND(員工清單!J9*參數設定!$C$8*參數設定!$C$10,0)) -> 2914 | AA9: =IF($A9="","",ROUND(員工清單!K9*參數設定!$C$11,0)) -> 70 | AB9: =IF($A9="","",ROUND(員工清單!L9*參數設定!$C$12*參數設定!$C$14*(1+參數設定!$C$15),0)) -> 1611 | AC9: =IF($A9="","",ROUND(員工清單!M9*參數設定!$C$17,0)) -> 1998 | AD9: =IF($A9="","",Z9+AA9+AB9+AC9) -> 6593 | AE9: =IF($A9="","",M9+AD9) -> 39593
A10: =IF(員工清單!A10="","",員工清單!A10) -> E007 | B10: =IF($A10="","",員工清單!B10) -> 吳建宏 | C10: =IF($A10="","",員工清單!C10) -> 製造部 | D10: =IF($A10="","",員工清單!I10) -> 29500 | J10: =IF($A10="","",ROUND($D10/參數設定!$C$19*(E10*4/3+F10*5/3+G10*4/3+H10*5/3+I10),0)) -> 0 | M10: =IF($A10="","",ROUND(D10+J10+K10+L10,0)) -> 29500 | N10: 8 | O10: 16 | P10: =IF($A10="","",ROUND($D10/參數設定!$C$19*(N10+O10*0.5),0)) -> 1967 | Q10: =IF($A10="","",ROUND(員工清單!J10*參數設定!$C$8*參數設定!$C$9,0)) -> 738 | R10: =IF($A10="","",ROUND(員工清單!L10*參數設定!$C$12*參數設定!$C$13,0)*(1+員工清單!O10)) -> 1832 | S10: =IF($A10="","",ROUND(員工清單!M10*N(員工清單!P10),0)) -> 0 | U10: =IF($A10="","",ROUND(MIN(N(L10),MAX(0,N(T10)-員工清單!L10*4))*參數設定!$C$18,0)) -> 0 | X10: =IF($A10="","",P10+Q10+R10+S10+U10+V10+W10) -> 4537 | Y10: =IF($A10="","",M10-X10) -> 24963 | Z10: =IF($A10="","",ROUND(員工清單!J10*參數設定!$C$8*參數設定!$C$10,0)) -> 2581 | AA10: =IF($A10="","",ROUND(員工清單!K10*參數設定!$C$11,0)) -> 62 | AB10: =IF($A10="","",ROUND(員工清單!L10*參數設定!$C$12*參數設定!$C$14*(1+參數設定!$C$15),0)) -> 1428 | AC10: =IF($A10="","",ROUND(員工清單!M10*參數設定!$C$17,0)) -> 1770 | AD10: =IF($A10="","",Z10+AA10+AB10+AC10) -> 5841 | AE10: =IF($A10="","",M10+AD10) -> 35341
A11: =IF(員工清單!A11="","",員工清單!A11) -> E008 | B11: =IF($A11="","",員工清單!B11) -> 蔡佩珊 | C11: =IF($A11="","",員工清單!C11) -> 總經理室 | D11: =IF($A11="","",員工清單!I11) -> 160000 | J11: =IF($A11="","",ROUND($D11/參數設定!$C$19*(E11*4/3+F11*5/3+G11*4/3+H11*5/3+I11),0)) -> 0 | L11: 100000 | M11: =IF($A11="","",ROUND(D11+J11+K11+L11,0)) -> 260000 | P11: =IF($A11="","",ROUND($D11/參數設定!$C$19*(N11+O11*0.5),0)) -> 0 | Q11: =IF($A11="","",ROUND(員工清單!J11*參數設定!$C$8*參數設定!$C$9,0)) -> 1145 | R11: =IF($A11="","",ROUND(員工清單!L11*參數設定!$C$12*參數設定!$C$13,0)*(1+員工清單!O11)) -> 5050 | S11: =IF($A11="","",ROUND(員工清單!M11*N(員工清單!P11),0)) -> 9000 | T11: 700000 | U11: =IF($A11="","",ROUND(MIN(N(L11),MAX(0,N(T11)-員工清單!L11*4))*參數設定!$C$18,0)) -> 1030 | V11: 12000 | X11: =IF($A11="","",P11+Q11+R11+S11+U11+V11+W11) -> 28225 | Y11: =IF($A11="","",M11-X11) -> 231775 | Z11: =IF($A11="","",ROUND(員工清單!J11*參數設定!$C$8*參數設定!$C$10,0)) -> 4007 | AA11: =IF($A11="","",ROUND(員工清單!K11*參數設定!$C$11,0)) -> 153 | AB11: =IF($A11="","",ROUND(員工清單!L11*參數設定!$C$12*參數設定!$C$14*(1+參數設定!$C$15),0)) -> 7878 | AC11: =IF($A11="","",ROUND(員工清單!M11*參數設定!$C$17,0)) -> 9000 | AD11: =IF($A11="","",Z11+AA11+AB11+AC11) -> 21038 | AE11: =IF($A11="","",M11+AD11) -> 281038
A12: =IF(員工清單!A12="","",員工清單!A12) | B12: =IF($A12="","",員工清單!B12) | C12: =IF($A12="","",員工清單!C12) | D12: =IF($A12="","",員工清單!I12) | J12: =IF($A12="","",ROUND($D12/參數設定!$C$19*(E12*4/3+F12*5/3+G12*4/3+H12*5/3+I12),0)) | M12: =IF($A12="","",ROUND(D12+J12+K12+L12,0)) | P12: =IF($A12="","",ROUND($D12/參數設定!$C$19*(N12+O12*0.5),0)) | Q12: =IF($A12="","",ROUND(員工清單!J12*參數設定!$C$8*參數設定!$C$9,0)) | R12: =IF($A12="","",ROUND(員工清單!L12*參數設定!$C$12*參數設定!$C$13,0)*(1+員工清單!O12)) | S12: =IF($A12="","",ROUND(員工清單!M12*N(員工清單!P12),0)) | U12: =IF($A12="","",ROUND(MIN(N(L12),MAX(0,N(T12)-員工清單!L12*4))*參數設定!$C$18,0)) | X12: =IF($A12="","",P12+Q12+R12+S12+U12+V12+W12) | Y12: =IF($A12="","",M12-X12) | Z12: =IF($A12="","",ROUND(員工清單!J12*參數設定!$C$8*參數設定!$C$10,0)) | AA12: =IF($A12="","",ROUND(員工清單!K12*參數設定!$C$11,0)) | AB12: =IF($A12="","",ROUND(員工清單!L12*參數設定!$C$12*參數設定!$C$14*(1+參數設定!$C$15),0)) | AC12: =IF($A12="","",ROUND(員工清單!M12*參數設定!$C$17,0)) | AD12: =IF($A12="","",Z12+AA12+AB12+AC12) | AE12: =IF($A12="","",M12+AD12)
A13: =IF(員工清單!A13="","",員工清單!A13) | B13: =IF($A13="","",員工清單!B13) | C13: =IF($A13="","",員工清單!C13) | D13: =IF($A13="","",員工清單!I13) | J13: =IF($A13="","",ROUND($D13/參數設定!$C$19*(E13*4/3+F13*5/3+G13*4/3+H13*5/3+I13),0)) | M13: =IF($A13="","",ROUND(D13+J13+K13+L13,0)) | P13: =IF($A13="","",ROUND($D13/參數設定!$C$19*(N13+O13*0.5),0)) | Q13: =IF($A13="","",ROUND(員工清單!J13*參數設定!$C$8*參數設定!$C$9,0)) | R13: =IF($A13="","",ROUND(員工清單!L13*參數設定!$C$12*參數設定!$C$13,0)*(1+員工清單!O13)) | S13: =IF($A13="","",ROUND(員工清單!M13*N(員工清單!P13),0)) | U13: =IF($A13="","",ROUND(MIN(N(L13),MAX(0,N(T13)-員工清單!L13*4))*參數設定!$C$18,0)) | X13: =IF($A13="","",P13+Q13+R13+S13+U13+V13+W13) | Y13: =IF($A13="","",M13-X13) | Z13: =IF($A13="","",ROUND(員工清單!J13*參數設定!$C$8*參數設定!$C$10,0)) | AA13: =IF($A13="","",ROUND(員工清單!K13*參數設定!$C$11,0)) | AB13: =IF($A13="","",ROUND(員工清單!L13*參數設定!$C$12*參數設定!$C$14*(1+參數設定!$C$15),0)) | AC13: =IF($A13="","",ROUND(員工清單!M13*參數設定!$C$17,0)) | AD13: =IF($A13="","",Z13+AA13+AB13+AC13) | AE13: =IF($A13="","",M13+AD13)
